Workbook
Name alpha: PARAMETRES!$B$13
Name beta: PARAMETRES!$B$14
Name gamma: PARAMETRES!$B$15
Name i: #REF!
Name i_tech: PARAMETRES!$B$7
Name r_pret: PARAMETRES!$B$8
Name v: #REF!

Sheet CIMA_F (décès)
A1: Age | B1: Lx (CIMA F) | C1: qx (CIMA F) | D1: dx (CIMA F) | E1: Px | F1: Dx | G1: Cx | H1: Mx | I1: Nx
A2: 0 | B2: 1000000 | C2: =IF(B2=0,1,D2/B2) -> 0.0028485034 | D2: =+B2-B3 -> 2848.5034 | F2: =B2*POWER($M$5,A2) -> 1000000 | G2: =D2*POWER($M$5,A2+0.5) -> 2799.9261 | H2: =SUM(G2:$G$112) -> 76890.047 | I2: =SUM(F2:$F$112) -> 27336456
A3: 1 | B3: 997151.5 | C3: =IF(B3=0,1,D3/B3) -> 0.00038696672 | D3: =+B3-B4 -> 385.86445 | F3: =B3*POWER($M$5,A3) -> 963431.4 | G3: =D3*POWER($M$5,A3+0.5) -> 366.45803 | H3: =SUM(G3:$G$112) -> 74090.12 | I3: =SUM(F3:$F$112) -> 26336456 | M3: =3.5/100 -> 0.035
A4: 2 | B4: 996765.63 | C4: =IF(B4=0,1,D4/B4) -> 0.00029622979 | D4: =+B4-B5 -> 295.27168 | F4: =B4*POWER($M$5,A4) -> 930491.38 | G4: =D4*POWER($M$5,A4+0.5) -> 270.93862 | H4: =SUM(G4:$G$112) -> 73723.662 | I4: =SUM(F4:$F$112) -> 25373024 | L4: i | M4: %
A5: 3 | B5: 996470.36 | C5: =IF(B5=0,1,D5/B5) -> 0.0002524072 | D5: =+B5-B6 -> 251.5163 | F5: =B5*POWER($M$5,A5) -> 898759.17 | G5: =D5*POWER($M$5,A5+0.5) -> 222.98462 | H5: =SUM(G5:$G$112) -> 73452.724 | I5: =SUM(F5:$F$112) -> 24442533 | L5: v | M5: =1/(1+M3) -> 0.96618357
A6: 4 | B6: 996218.84 | C6: =IF(B6=0,1,D6/B6) -> 0.0002157539 | D6: =+B6-B7 -> 214.9381 | F6: =B6*POWER($M$5,A6) -> 868147.17 | G6: =D6*POWER($M$5,A6+0.5) -> 184.11189 | H6: =SUM(G6:$G$112) -> 73229.739 | I6: =SUM(F6:$F$112) -> 23543774
A7: 5 | B7: 996003.91 | C7: =IF(B7=0,1,D7/B7) -> 0.00019677924 | D7: =+B7-B8 -> 195.99289 | F7: =B7*POWER($M$5,A7) -> 838608.56 | G7: =D7*POWER($M$5,A7+0.5) -> 162.20655 | H7: =SUM(G7:$G$112) -> 73045.627 | I7: =SUM(F7:$F$112) -> 22675627
A8: 6 | B8: 995807.91 | C8: =IF(B8=0,1,D8/B8) -> 0.00017727153 | D8: =+B8-B9 -> 176.52839 | F8: =B8*POWER($M$5,A8) -> 810090.38 | G8: =D8*POWER($M$5,A8+0.5) -> 141.15696 | H8: =SUM(G8:$G$112) -> 72883.421 | I8: =SUM(F8:$F$112) -> 21837018
A9: 7 | B9: 995631.38 | C9: =IF(B9=0,1,D9/B9) -> 0.00016729893 | D9: =+B9-B10 -> 166.56807 | F9: =B9*POWER($M$5,A9) -> 782557.27 | G9: =D9*POWER($M$5,A9+0.5) -> 128.68832 | H9: =SUM(G9:$G$112) -> 72742.264 | I9: =SUM(F9:$F$112) -> 21026928 | L9: Cas pratique
A10: 8 | B10: 995464.82 | C10: =IF(B10=0,1,D10/B10) -> 0.00016731606 | D10: =+B10-B11 -> 166.55725 | F10: =B10*POWER($M$5,A10) -> 755967.49 | G10: =D10*POWER($M$5,A10+0.5) -> 124.32847 | H10: =SUM(G10:$G$112) -> 72613.575 | I10: =SUM(F10:$F$112) -> 20244370
A11: 9 | B11: 995298.26 | C11: =IF(B11=0,1,D11/B11) -> 0.00015717038 | D11: =+B11-B12 -> 156.43141 | F11: =B11*POWER($M$5,A11) -> 730281.16 | G11: =D11*POWER($M$5,A11+0.5) -> 112.82118 | H11: =SUM(G11:$G$112) -> 72489.247 | I11: =SUM(F11:$F$112) -> 19488403 | L11: x | M11: 40
A12: 10 | B12: 995141.83 | C12: =IF(B12=0,1,D12/B12) -> 0.00016734902 | D12: =+B12-B13 -> 166.53601 | F12: =B12*POWER($M$5,A12) -> 705474.76 | G12: =D12*POWER($M$5,A12+0.5) -> 116.04715 | H12: =SUM(G12:$G$112) -> 72376.426 | I12: =SUM(F12:$F$112) -> 18758122 | L12: C | M12: 5000000
A13: 11 | B13: 994975.29 | C13: =IF(B13=0,1,D13/B13) -> 0.00016736617 | D13: =+B13-B14 -> 166.5252 | F13: =B13*POWER($M$5,A13) -> 681504.06 | G13: =D13*POWER($M$5,A13+0.5) -> 112.11558 | H13: =SUM(G13:$G$112) -> 72260.379 | I13: =SUM(F13:$F$112) -> 18052647 | L13: d | M13: 5
A14: 12 | B14: 994808.77 | C14: =IF(B14=0,1,D14/B14) -> 0.00019692502 | D14: =+B14-B15 -> 195.90274 | F14: =B14*POWER($M$5,A14) -> 658347.83 | G14: =D14*POWER($M$5,A14+0.5) -> 127.43424 | H14: =SUM(G14:$G$112) -> 72148.263 | I14: =SUM(F14:$F$112) -> 17371143 | L14: P | M14: =(M12*(F47/F42)/(1+(F43/F42)+(F44/F42)+(F45/F42)+(F46/F42))) -> 894327.77
A15: 13 | B15: 994612.86 | C15: =IF(B15=0,1,D15/B15) -> 0.00023453851 | D15: =+B15-B16 -> 233.27502 | F15: =B15*POWER($M$5,A15) -> 635959.6 | G15: =D15*POWER($M$5,A15+0.5) -> 146.61335 | H15: =SUM(G15:$G$112) -> 72020.829 | I15: =SUM(F15:$F$112) -> 16712795 | M15: =F47/(I42-I47)*M12 -> 894327.77
A16: 14 | B16: 994379.59 | C16: =IF(B16=0,1,D16/B16) -> 0.00028805339 | D16: =+B16-B17 -> 286.43442 | F16: =B16*POWER($M$5,A16) -> 614309.6 | G16: =D16*POWER($M$5,A16+0.5) -> 173.93626 | H16: =SUM(G16:$G$112) -> 71874.216 | I16: =SUM(F16:$F$112) -> 16076835
A17: 15 | B17: 994093.15 | C17: =IF(B17=0,1,D17/B17) -> 0.00037975267 | D17: =+B17-B18 -> 377.50953 | F17: =B17*POWER($M$5,A17) -> 593364.88 | G17: =D17*POWER($M$5,A17+0.5) -> 221.48917 | H17: =SUM(G17:$G$112) -> 71700.279 | I17: =SUM(F17:$F$112) -> 15462526 | L17: f mensuelle | M17: 1.04
A18: 16 | B18: 993715.65 | C18: =IF(B18=0,1,D18/B18) -> 0.00048082161 | D18: =+B18-B19 -> 477.79995 | F18: =B18*POWER($M$5,A18) -> 573081.69 | G18: =D18*POWER($M$5,A18+0.5) -> 270.85093 | H18: =SUM(G18:$G$112) -> 71478.79 | I18: =SUM(F18:$F$112) -> 14869161 | L18: f semestrielle | M18: 1.02
A19: 17 | B19: 993237.85 | C19: =IF(B19=0,1,D19/B19) -> 0.00059776603 | D19: =+B19-B20 -> 593.72384 | F19: =B19*POWER($M$5,A19) -> 553435.88 | G19: =D19*POWER($M$5,A19+0.5) -> 325.1834 | H19: =SUM(G19:$G$112) -> 71207.939 | I19: =SUM(F19:$F$112) -> 14296079 | L19: f trimestrielle | M19: 1.03
A20: 18 | B20: 992644.12 | C20: =IF(B20=0,1,D20/B20) -> 0.00070883395 | D20: =+B20-B21 -> 703.61985 | F20: =B20*POWER($M$5,A20) -> 534401.02 | G20: =D20*POWER($M$5,A20+0.5) -> 372.34165 | H20: =SUM(G20:$G$112) -> 70882.756 | I20: =SUM(F20:$F$112) -> 13742643 | L20: P mensuelle | M20: =M15*M17/12 -> 77508.407
A21: 19 | B21: 991940.5 | C21: =IF(B21=0,1,D21/B21) -> 0.00078931864 | D21: =+B21-B22 -> 782.95712 | F21: =B21*POWER($M$5,A21) -> 515963.5 | G21: =D21*POWER($M$5,A21+0.5) -> 400.31435 | H21: =SUM(G21:$G$112) -> 70510.414 | I21: =SUM(F21:$F$112) -> 13208242 | L21: P semestrielle | M21: =M15*M18/2 -> 456107.16
A22: 20 | B22: 991157.54 | C22: =IF(B22=0,1,D22/B22) -> 0.00083637012 | D22: =+B22-B23 -> 828.97456 | F22: =B22*POWER($M$5,A22) -> 498121.97 | G22: =D22*POWER($M$5,A22+0.5) -> 409.50955 | H22: =SUM(G22:$G$112) -> 70110.1 | I22: =SUM(F22:$F$112) -> 12692279 | L22: P trimestrielle | M22: =M15*M19/4 -> 230289.4
A23: 21 | B23: 990328.57 | C23: =IF(B23=0,1,D23/B23) -> 0.00086647736 | D23: =+B23-B24 -> 858.09728 | F23: =B23*POWER($M$5,A23) -> 480874.74 | G23: =D23*POWER($M$5,A23+0.5) -> 409.56139 | H23: =SUM(G23:$G$112) -> 69700.59 | I23: =SUM(F23:$F$112) -> 12194157
A24: 22 | B24: 989470.47 | C24: =IF(B24=0,1,D24/B24) -> 0.00088622751 | D24: =+B24-B25 -> 876.89595 | F24: =B24*POWER($M$5,A24) -> 464210.7 | G24: =D24*POWER($M$5,A24+0.5) -> 404.38049 | H24: =SUM(G24:$G$112) -> 69291.029 | I24: =SUM(F24:$F$112) -> 11713282
A25: 23 | B25: 988593.58 | C25: =IF(B25=0,1,D25/B25) -> 0.00090252101 | D25: =+B25-B26 -> 892.22648 | F25: =B25*POWER($M$5,A25) -> 448115.27 | G25: =D25*POWER($M$5,A25+0.5) -> 397.53639 | H25: =SUM(G25:$G$112) -> 68886.648 | I25: =SUM(F25:$F$112) -> 11249072
A26: 24 | B26: 987701.35 | C26: =IF(B26=0,1,D26/B26) -> 0.00092226611 | D26: =+B26-B27 -> 910.92348 | F26: =B26*POWER($M$5,A26) -> 432570.85 | G26: =D26*POWER($M$5,A26+0.5) -> 392.14197 | H26: =SUM(G26:$G$112) -> 68489.112 | I26: =SUM(F26:$F$112) -> 10800956
A27: 25 | B27: 986790.43 | C27: =IF(B27=0,1,D27/B27) -> 0.00094201191 | D27: =+B27-B28 -> 929.56833 | F27: =B27*POWER($M$5,A27) -> 417557.4 | G27: =D27*POWER($M$5,A27+0.5) -> 386.6361 | H27: =SUM(G27:$G$112) -> 68096.97 | I27: =SUM(F27:$F$112) -> 10368385
A28: 26 | B28: 985860.86 | C28: =IF(B28=0,1,D28/B28) -> 0.00096868291 | D28: =+B28-B29 -> 954.98656 | F28: =B28*POWER($M$5,A28) -> 403057.06 | G28: =D28*POWER($M$5,A28+0.5) -> 383.77616 | H28: =SUM(G28:$G$112) -> 67710.334 | I28: =SUM(F28:$F$112) -> 9950828
A29: 27 | B29: 984905.87 | C29: =IF(B29=0,1,D29/B29) -> 0.00099534487 | D29: =+B29-B30 -> 980.32101 | F29: =B29*POWER($M$5,A29) -> 389049.88 | G29: =D29*POWER($M$5,A29+0.5) -> 380.63497 | H29: =SUM(G29:$G$112) -> 67326.558 | I29: =SUM(F29:$F$112) -> 9547770.9
A30: 28 | B30: 983925.55 | C30: =IF(B30=0,1,D30/B30) -> 0.0010219988 | D30: =+B30-B31 -> 1005.5707 | F30: =B30*POWER($M$5,A30) -> 375519.46 | G30: =D30*POWER($M$5,A30+0.5) -> 377.23558 | H30: =SUM(G30:$G$112) -> 66945.923 | I30: =SUM(F30:$F$112) -> 9158721.1
A31: 29 | B31: 982919.98 | C31: =IF(B31=0,1,D31/B31) -> 0.0010506117 | D31: =+B31-B32 -> 1032.6672 | F31: =B31*POWER($M$5,A31) -> 362449.93 | G31: =D31*POWER($M$5,A31+0.5) -> 374.30022 | H31: =SUM(G31:$G$112) -> 66568.687 | I31: =SUM(F31:$F$112) -> 8783201.6
A32: 30 | B32: 981887.31 | C32: =IF(B32=0,1,D32/B32) -> 0.0010753558 | D32: =+B32-B33 -> 1055.8782 | F32: =B32*POWER($M$5,A32) -> 349825.25 | G32: =D32*POWER($M$5,A32+0.5) -> 369.77125 | H32: =SUM(G32:$G$112) -> 66194.387 | I32: =SUM(F32:$F$112) -> 8420751.7
A33: 31 | B33: 980831.43 | C33: =IF(B33=0,1,D33/B33) -> 0.0010988285 | D33: =+B33-B34 -> 1077.7655 | F33: =B33*POWER($M$5,A33) -> 337631.95 | G33: =D33*POWER($M$5,A33+0.5) -> 364.67271 | H33: =SUM(G33:$G$112) -> 65824.616 | I33: =SUM(F33:$F$112) -> 8070926.4
A34: 32 | B34: 979753.67 | C34: =IF(B34=0,1,D34/B34) -> 0.0011371107 | D34: =+B34-B35 -> 1114.0884 | F34: =B34*POWER($M$5,A34) -> 325855.99 | G34: =D34*POWER($M$5,A34+0.5) -> 364.21537 | H34: =SUM(G34:$G$112) -> 65459.943 | I34: =SUM(F34:$F$112) -> 7733294.5
... A112: 110 | B112: 0 | C112: =IF(B112=0,1,D112/B112) -> 1 | D112: =+B112-B113 -> 0 | F112: =B112*POWER($M$5,A112) -> 0 | G112: =D112*POWER($M$5,A112+0.5) -> 0 | H112: =SUM(G112:$G$112) -> 0 | I112: =SUM(F112:$F$112) -> 0

Sheet CIMA_H (décès)
A1: Age | B1: Lx (CIMA H) | C1: qx (CIMA H) | D1: dx (CIMA H) | E1: Px | F1: Dx | G1: Cx | H1: Mx | I1: Nx
A2: 0 | B2: 1000000 | C2: =IF(B2=0,1,D2/B2) -> 0.0053677459 | D2: =+B2-B3 -> 5367.7459 | F2: =B2*POWER($M$5,A2) -> 1000000 | G2: =D2*POWER($M$5,A2+0.5) -> 5276.2064 | H2: =SUM(G2:$G$112) -> 103402.46 | I2: =SUM(F2:$F$112) -> 26565816
A3: 1 | B3: 994632.25 | C3: =IF(B3=0,1,D3/B3) -> 0.00073000062 | D3: =+B3-B4 -> 726.08216 | F3: =B3*POWER($M$5,A3) -> 960997.35 | G3: =D3*POWER($M$5,A3+0.5) -> 689.56505 | H3: =SUM(G3:$G$112) -> 98126.254 | I3: =SUM(F3:$F$112) -> 25565816 | L3: i | M3: =3.5/100 -> 0.035
A4: 2 | B4: 993906.17 | C4: =IF(B4=0,1,D4/B4) -> 0.00055885073 | D4: =+B4-B5 -> 555.44519 | F4: =B4*POWER($M$5,A4) -> 927822.05 | G4: =D4*POWER($M$5,A4+0.5) -> 509.67148 | H4: =SUM(G4:$G$112) -> 97436.689 | I4: =SUM(F4:$F$112) -> 24604819
A5: 3 | B5: 993350.73 | C5: =IF(B5=0,1,D5/B5) -> 0.00047618671 | D5: =+B5-B6 -> 473.02041 | F5: =B5*POWER($M$5,A5) -> 895945.44 | G5: =D5*POWER($M$5,A5+0.5) -> 419.3616 | H5: =SUM(G5:$G$112) -> 96927.017 | I5: =SUM(F5:$F$112) -> 23676997 | L5: v | M5: =1/(1+M3) -> 0.96618357
A6: 4 | B6: 992877.71 | C6: =IF(B6=0,1,D6/B6) -> 0.00040704388 | D6: =+B6-B7 -> 404.1448 | F6: =B6*POWER($M$5,A6) -> 865235.56 | G6: =D6*POWER($M$5,A6+0.5) -> 346.18274 | H6: =SUM(G6:$G$112) -> 96507.655 | I6: =SUM(F6:$F$112) -> 22781051
A7: 5 | B7: 992473.56 | C7: =IF(B7=0,1,D7/B7) -> 0.00037124919 | D7: =+B7-B8 -> 368.455 | F7: =B7*POWER($M$5,A7) -> 835636.11 | G7: =D7*POWER($M$5,A7+0.5) -> 304.93869 | H7: =SUM(G7:$G$112) -> 96161.473 | I7: =SUM(F7:$F$112) -> 21915816
A8: 6 | B8: 992105.11 | C8: =IF(B8=0,1,D8/B8) -> 0.0003344483 | D8: =+B8-B9 -> 331.80786 | F8: =B8*POWER($M$5,A8) -> 807078.14 | G8: =D8*POWER($M$5,A8+0.5) -> 265.32269 | H8: =SUM(G8:$G$112) -> 95856.534 | I8: =SUM(F8:$F$112) -> 21080179
A9: 7 | B9: 991773.3 | C9: =IF(B9=0,1,D9/B9) -> 0.00031563494 | D9: =+B9-B10 -> 313.03831 | F9: =B9*POWER($M$5,A9) -> 779524.85 | G9: =D9*POWER($M$5,A9+0.5) -> 241.84932 | H9: =SUM(G9:$G$112) -> 95591.211 | I9: =SUM(F9:$F$112) -> 20273101 | L9: Cas pratique
A10: 8 | B10: 991460.26 | C10: =IF(B10=0,1,D10/B10) -> 0.00031566727 | D10: =+B10-B11 -> 312.97155 | F10: =B10*POWER($M$5,A10) -> 752926.38 | G10: =D10*POWER($M$5,A10+0.5) -> 233.621 | H10: =SUM(G10:$G$112) -> 95349.362 | I10: =SUM(F10:$F$112) -> 19493576
A11: 9 | B11: 991147.29 | C11: =IF(B11=0,1,D11/B11) -> 0.00029652722 | D11: =+B11-B12 -> 293.90215 | F11: =B11*POWER($M$5,A11) -> 727235.46 | G11: =D11*POWER($M$5,A11+0.5) -> 211.96758 | H11: =SUM(G11:$G$112) -> 95115.741 | I11: =SUM(F11:$F$112) -> 18740650 | L11: x | M11: 40
A12: 10 | B12: 990853.39 | C12: =IF(B12=0,1,D12/B12) -> 0.00031572945 | D12: =+B12-B13 -> 312.84159 | F12: =B12*POWER($M$5,A12) -> 702434.61 | G12: =D12*POWER($M$5,A12+0.5) -> 217.99715 | H12: =SUM(G12:$G$112) -> 94903.773 | I12: =SUM(F12:$F$112) -> 18013415 | L12: C | M12: 5000000
A13: 11 | B13: 990540.55 | C13: =IF(B13=0,1,D13/B13) -> 0.00031576179 | D13: =+B13-B14 -> 312.77486 | F13: =B13*POWER($M$5,A13) -> 678466.5 | G13: =D13*POWER($M$5,A13+0.5) -> 210.58033 | H13: =SUM(G13:$G$112) -> 94685.776 | I13: =SUM(F13:$F$112) -> 17310980 | L13: d | M13: 5
A14: 12 | B14: 990227.77 | C14: =IF(B14=0,1,D14/B14) -> 0.0003715242 | D14: =+B14-B15 -> 367.89358 | F14: =B14*POWER($M$5,A14) -> 655316.2 | G14: =D14*POWER($M$5,A14+0.5) -> 239.31385 | H14: =SUM(G14:$G$112) -> 94475.196 | I14: =SUM(F14:$F$112) -> 16632514 | L14: P | M14: =(M12*(F47/F42)/(1+(F43/F42)+(F44/F42)+(F45/F42)+(F46/F42))) -> 888788.18
A15: 13 | B15: 989859.88 | C15: =IF(B15=0,1,D15/B15) -> 0.00044247948 | D15: =+B15-B16 -> 437.99268 | F15: =B15*POWER($M$5,A15) -> 632920.52 | G15: =D15*POWER($M$5,A15+0.5) -> 275.2784 | H15: =SUM(G15:$G$112) -> 94235.882 | I15: =SUM(F15:$F$112) -> 15977197 | M15: =F47/(I42-I47)*M12 -> 888788.18
A16: 14 | B16: 989421.88 | C16: =IF(B16=0,1,D16/B16) -> 0.00054342755 | D16: =+B16-B17 -> 537.67911 | F16: =B16*POWER($M$5,A16) -> 611246.82 | G16: =D16*POWER($M$5,A16+0.5) -> 326.50369 | H16: =SUM(G16:$G$112) -> 93960.604 | I16: =SUM(F16:$F$112) -> 15344277
A17: 15 | B17: 988884.2 | C17: =IF(B17=0,1,D17/B17) -> 0.00071639382 | D17: =+B17-B18 -> 708.43053 | F17: =B17*POWER($M$5,A17) -> 590255.7 | G17: =D17*POWER($M$5,A17+0.5) -> 415.64432 | H17: =SUM(G17:$G$112) -> 93634.1 | I17: =SUM(F17:$F$112) -> 14733030 | L17: f mensuelle | M17: 1.04
A18: 16 | B18: 988175.77 | C18: =IF(B18=0,1,D18/B18) -> 0.00090701716 | D18: =+B18-B19 -> 896.29238 | F18: =B18*POWER($M$5,A18) -> 569886.81 | G18: =D18*POWER($M$5,A18+0.5) -> 508.08215 | H18: =SUM(G18:$G$112) -> 93218.456 | I18: =SUM(F18:$F$112) -> 14142774 | L18: f semestrielle | M18: 1.02
A19: 17 | B19: 987279.48 | C19: =IF(B19=0,1,D19/B19) -> 0.0011275615 | D19: =+B19-B20 -> 1113.2183 | F19: =B19*POWER($M$5,A19) -> 550115.86 | G19: =D19*POWER($M$5,A19+0.5) -> 609.71127 | H19: =SUM(G19:$G$112) -> 92710.374 | I19: =SUM(F19:$F$112) -> 13572887 | L19: f trimestrielle | M19: 1.03
A20: 18 | B20: 986166.26 | C20: =IF(B20=0,1,D20/B20) -> 0.0013370022 | D20: =+B20-B21 -> 1318.5065 | F20: =B20*POWER($M$5,A20) -> 530913.59 | G20: =D20*POWER($M$5,A20+0.5) -> 697.72742 | H20: =SUM(G20:$G$112) -> 92100.662 | I20: =SUM(F20:$F$112) -> 13022772 | L20: P mensuelle | M20: =M15*M17/12 -> 77028.309
A21: 19 | B21: 984847.76 | C21: =IF(B21=0,1,D21/B21) -> 0.0014887592 | D21: =+B21-B22 -> 1466.2012 | F21: =B21*POWER($M$5,A21) -> 512274.17 | G21: =D21*POWER($M$5,A21+0.5) -> 749.64689 | H21: =SUM(G21:$G$112) -> 91402.935 | I21: =SUM(F21:$F$112) -> 12491858 | L21: P semestrielle | M21: =M15*M18/2 -> 453281.97
A22: 20 | B22: 983381.56 | C22: =IF(B22=0,1,D22/B22) -> 0.0015776776 | D22: =+B22-B23 -> 1551.459 | F22: =B22*POWER($M$5,A22) -> 494214.02 | G22: =D22*POWER($M$5,A22+0.5) -> 766.4135 | H22: =SUM(G22:$G$112) -> 90653.288 | I22: =SUM(F22:$F$112) -> 11979584 | L22: P trimestrielle | M22: =M15*M19/4 -> 228862.96
A23: 21 | B23: 981830.1 | C23: =IF(B23=0,1,D23/B23) -> 0.0016325206 | D23: =+B23-B24 -> 1602.8579 | F23: =B23*POWER($M$5,A23) -> 476748.13 | G23: =D23*POWER($M$5,A23+0.5) -> 765.0283 | H23: =SUM(G23:$G$112) -> 89886.874 | I23: =SUM(F23:$F$112) -> 11485370
A24: 22 | B24: 980227.24 | C24: =IF(B24=0,1,D24/B24) -> 0.0016645249 | D24: =+B24-B25 -> 1631.6126 | F24: =B24*POWER($M$5,A24) -> 459874.23 | G24: =D24*POWER($M$5,A24+0.5) -> 752.41803 | H24: =SUM(G24:$G$112) -> 89121.846 | I24: =SUM(F24:$F$112) -> 11008622
A25: 23 | B25: 978595.63 | C25: =IF(B25=0,1,D25/B25) -> 0.0016889068 | D25: =+B25-B26 -> 1652.7568 | F25: =B25*POWER($M$5,A25) -> 443583.34 | G25: =D25*POWER($M$5,A25+0.5) -> 736.39484 | H25: =SUM(G25:$G$112) -> 88369.428 | I25: =SUM(F25:$F$112) -> 10548747
A26: 24 | B26: 976942.87 | C26: =IF(B26=0,1,D26/B26) -> 0.0017208999 | D26: =+B26-B27 -> 1681.2209 | F26: =B26*POWER($M$5,A26) -> 427859.1 | G26: =D26*POWER($M$5,A26+0.5) -> 723.74606 | H26: =SUM(G26:$G$112) -> 87633.033 | I26: =SUM(F26:$F$112) -> 10105164
A27: 25 | B27: 975261.65 | C27: =IF(B27=0,1,D27/B27) -> 0.0017528946 | D27: =+B27-B28 -> 1709.5308 | F27: =B27*POWER($M$5,A27) -> 412679.03 | G27: =D27*POWER($M$5,A27+0.5) -> 711.04653 | H27: =SUM(G27:$G$112) -> 86909.287 | I27: =SUM(F27:$F$112) -> 9677305
A28: 26 | B28: 973552.12 | C28: =IF(B28=0,1,D28/B28) -> 0.0018001601 | D28: =+B28-B29 -> 1752.5496 | F28: =B28*POWER($M$5,A28) -> 398024.78 | G28: =D28*POWER($M$5,A28+0.5) -> 704.28925 | H28: =SUM(G28:$G$112) -> 86198.241 | I28: =SUM(F28:$F$112) -> 9264626
A29: 27 | B29: 971799.57 | C29: =IF(B29=0,1,D29/B29) -> 0.0018474054 | D29: =+B29-B30 -> 1795.3078 | F29: =B29*POWER($M$5,A29) -> 383872.73 | G29: =D29*POWER($M$5,A29+0.5) -> 697.07466 | H29: =SUM(G29:$G$112) -> 85493.951 | I29: =SUM(F29:$F$112) -> 8866601.2
A30: 28 | B30: 970004.26 | C30: =IF(B30=0,1,D30/B30) -> 0.0018946329 | D30: =+B30-B31 -> 1837.8019 | F30: =B30*POWER($M$5,A30) -> 370206.34 | G30: =D30*POWER($M$5,A30+0.5) -> 689.44359 | H30: =SUM(G30:$G$112) -> 84796.877 | I30: =SUM(F30:$F$112) -> 8482728.5
A31: 29 | B31: 968166.46 | C31: =IF(B31=0,1,D31/B31) -> 0.0019478249 | D31: =+B31-B32 -> 1885.8187 | F31: =B31*POWER($M$5,A31) -> 357009.6 | G31: =D31*POWER($M$5,A31+0.5) -> 683.53322 | H31: =SUM(G31:$G$112) -> 84107.433 | I31: =SUM(F31:$F$112) -> 8112522.2
A32: 30 | B32: 966280.64 | C32: =IF(B32=0,1,D32/B32) -> 0.0019934237 | D32: =+B32-B33 -> 1926.2067 | F32: =B32*POWER($M$5,A32) -> 344264.93 | G32: =D32*POWER($M$5,A32+0.5) -> 674.56254 | H32: =SUM(G32:$G$112) -> 83423.9 | I32: =SUM(F32:$F$112) -> 7755512.6
A33: 31 | B33: 964354.43 | C33: =IF(B33=0,1,D33/B33) -> 0.0020367987 | D33: =+B33-B34 -> 1964.1958 | F33: =B33*POWER($M$5,A33) -> 331960.06 | G33: =D33*POWER($M$5,A33+0.5) -> 664.60525 | H33: =SUM(G33:$G$112) -> 82749.337 | I33: =SUM(F33:$F$112) -> 7411247.6
A34: 32 | B34: 962390.24 | C34: =IF(B34=0,1,D34/B34) -> 0.0021075329 | D34: =+B34-B35 -> 2028.269 | F34: =B34*POWER($M$5,A34) -> 320081.09 | G34: =D34*POWER($M$5,A34+0.5) -> 663.07735 | H34: =SUM(G34:$G$112) -> 82084.732 | I34: =SUM(F34:$F$112) -> 7079287.6
... A112: 110 | B112: 0 | C112: =IF(B112=0,1,D112/B112) -> 1 | D112: =+B112-B113 -> 0 | F112: =B112*POWER($M$5,A112) -> 0 | G112: =D112*POWER($M$5,A112+0.5) -> 0 | H112: =SUM(G112:$G$112) -> 0 | I112: =SUM(F112:$F$112) -> 0

Sheet DASHBOARD
A2: DASHBOARD — SYNTHÈSE DU PORTEFEUILLE DÉCÈS EMPRUNTEUR
A3: Mis à jour automatiquement depuis BASE_SOUSCRIPTEURS • Montants en FCFA
A5: Nombre d'assurés | C5: Nombre de contrats | E5: Capital total assuré | G5: Prime Pure totale
A6: =COUNTA(BASE_SOUSCRIPTEURS!B5:B14) -> 10 | C6: =SUMPRODUCT(1/COUNTIF(BASE_SOUSCRIPTEURS!A5:A14,BASE_SOUSCRIPTEURS!A5:A14)) -> 6 | E6: =BASE_SOUSCRIPTEURS!F15 -> 116000000 | G6: =BASE_SOUSCRIPTEURS!K15 -> 0
A11: Prime Commerciale totale | C11: PM totale (t=0) | E11: Taux moyen PC (‰) | G11: Taux technique (i)
A12: =BASE_SOUSCRIPTEURS!N15 -> 0 | C12: =PROVISIONS!H14 -> 0 | E12: =TABLEAU_PRIMES!H14 -> 3.6454192 | G12: =PARAMETRES!B7 -> 0.035
A19: Détail par contrat
A20: N° Contrat | B20: Nom(s) Assuré(s) | C20: Capital (FCFA) | D20: PP totale (FCFA) | E20: PC totale (FCFA/an) | F20: PM init. (FCFA) | G20: Taux PC (‰) | H20: % du portefeuille
A21: CTR-001 | B21: =IFERROR(INDEX(BASE_SOUSCRIPTEURS!$B$5:$B$14,MATCH(A21,BASE_SOUSCRIPTEURS!$A$5:$A$14,0)),"—") -> DIALLO Mamadou | C21: =SUMIF(BASE_SOUSCRIPTEURS!$A$5:$A$14,A21,BASE_SOUSCRIPTEURS!$F$5:$F$14) -> 30000000 | D21: =SUMIF(BASE_SOUSCRIPTEURS!$A$5:$A$14,A21,BASE_SOUSCRIPTEURS!$K$5:$K$14) -> 641375.9 | E21: =SUMIF(BASE_SOUSCRIPTEURS!$A$5:$A$14,A21,BASE_SOUSCRIPTEURS!$N$5:$N$14) -> 56991.231 | F21: =SUMIF(BASE_SOUSCRIPTEURS!$A$5:$A$14,A21,BASE_SOUSCRIPTEURS!$K$5:$K$14) -> 641375.9 | G21: =IF(C21=0,0,E21/C21*1000) -> 1.8997077 | H21: =IF(DASHBOARD!D27=0,0,D21/DASHBOARD!D27) -> 0.21604216
A22: CTR-002 | B22: =IFERROR(INDEX(BASE_SOUSCRIPTEURS!$B$5:$B$14,MATCH(A22,BASE_SOUSCRIPTEURS!$A$5:$A$14,0)),"—") -> SALL Ibrahim | C22: =SUMIF(BASE_SOUSCRIPTEURS!$A$5:$A$14,A22,BASE_SOUSCRIPTEURS!$F$5:$F$14) -> 10000000 | D22: =SUMIF(BASE_SOUSCRIPTEURS!$A$5:$A$14,A22,BASE_SOUSCRIPTEURS!$K$5:$K$14) -> 587191.27 | E22: =SUMIF(BASE_SOUSCRIPTEURS!$A$5:$A$14,A22,BASE_SOUSCRIPTEURS!$N$5:$N$14) -> 64836.285 | F22: =SUMIF(BASE_SOUSCRIPTEURS!$A$5:$A$14,A22,BASE_SOUSCRIPTEURS!$K$5:$K$14) -> 587191.27 | G22: =IF(C22=0,0,E22/C22*1000) -> 6.4836285 | H22: =IF(DASHBOARD!D27=0,0,D22/DASHBOARD!D27) -> 0.19779052
A23: CTR-003 | B23: =IFERROR(INDEX(BASE_SOUSCRIPTEURS!$B$5:$B$14,MATCH(A23,BASE_SOUSCRIPTEURS!$A$5:$A$14,0)),"—") -> NDIAYE Fatou | C23: =SUMIF(BASE_SOUSCRIPTEURS!$A$5:$A$14,A23,BASE_SOUSCRIPTEURS!$F$5:$F$14) -> 16000000 | D23: =SUMIF(BASE_SOUSCRIPTEURS!$A$5:$A$14,A23,BASE_SOUSCRIPTEURS!$K$5:$K$14) -> 271155.46 | E23: =SUMIF(BASE_SOUSCRIPTEURS!$A$5:$A$14,A23,BASE_SOUSCRIPTEURS!$N$5:$N$14) -> 35162.246 | F23: =SUMIF(BASE_SOUSCRIPTEURS!$A$5:$A$14,A23,BASE_SOUSCRIPTEURS!$K$5:$K$14) -> 271155.46 | G23: =IF(C23=0,0,E23/C23*1000) -> 2.1976404 | H23: =IF(DASHBOARD!D27=0,0,D23/DASHBOARD!D27) -> 0.091336472
A24: CTR-004 | B24: =IFERROR(INDEX(BASE_SOUSCRIPTEURS!$B$5:$B$14,MATCH(A24,BASE_SOUSCRIPTEURS!$A$5:$A$14,0)),"—") -> TOURE Aissatou | C24: =SUMIF(BASE_SOUSCRIPTEURS!$A$5:$A$14,A24,BASE_SOUSCRIPTEURS!$F$5:$F$14) -> 40000000 | D24: =SUMIF(BASE_SOUSCRIPTEURS!$A$5:$A$14,A24,BASE_SOUSCRIPTEURS!$K$5:$K$14) -> 670608.83 | E24: =SUMIF(BASE_SOUSCRIPTEURS!$A$5:$A$14,A24,BASE_SOUSCRIPTEURS!$N$5:$N$14) -> 51120.773 | F24: =SUMIF(BASE_SOUSCRIPTEURS!$A$5:$A$14,A24,BASE_SOUSCRIPTEURS!$K$5:$K$14) -> 670608.83 | G24: =IF(C24=0,0,E24/C24*1000) -> 1.2780193 | H24: =IF(DASHBOARD!D27=0,0,D24/DASHBOARD!D27) -> 0.22588903
A25: CTR-005 | B25: =IFERROR(INDEX(BASE_SOUSCRIPTEURS!$B$5:$B$14,MATCH(A25,BASE_SOUSCRIPTEURS!$A$5:$A$14,0)),"—") -> BARRY Mariama | C25: =SUMIF(BASE_SOUSCRIPTEURS!$A$5:$A$14,A25,BASE_SOUSCRIPTEURS!$F$5:$F$14) -> 5000000 | D25: =SUMIF(BASE_SOUSCRIPTEURS!$A$5:$A$14,A25,BASE_SOUSCRIPTEURS!$K$5:$K$14) -> 288166.52 | E25: =SUMIF(BASE_SOUSCRIPTEURS!$A$5:$A$14,A25,BASE_SOUSCRIPTEURS!$N$5:$N$14) -> 43917.288 | F25: =SUMIF(BASE_SOUSCRIPTEURS!$A$5:$A$14,A25,BASE_SOUSCRIPTEURS!$K$5:$K$14) -> 288166.52 | G25: =IF(C25=0,0,E25/C25*1000) -> 8.7834577 | H25: =IF(DASHBOARD!D27=0,0,D25/DASHBOARD!D27) -> 0.097066507
A26: CTR-006 | B26: =IFERROR(INDEX(BASE_SOUSCRIPTEURS!$B$5:$B$14,MATCH(A26,BASE_SOUSCRIPTEURS!$A$5:$A$14,0)),"—") -> CAMARA Seydou | C26: =SUMIF(BASE_SOUSCRIPTEURS!$A$5:$A$14,A26,BASE_SOUSCRIPTEURS!$F$5:$F$14) -> 15000000 | D26: =SUMIF(BASE_SOUSCRIPTEURS!$A$5:$A$14,A26,BASE_SOUSCRIPTEURS!$K$5:$K$14) -> 510255.4 | E26: =SUMIF(BASE_SOUSCRIPTEURS!$A$5:$A$14,A26,BASE_SOUSCRIPTEURS!$N$5:$N$14) -> 78272.786 | F26: =SUMIF(BASE_SOUSCRIPTEURS!$A$5:$A$14,A26,BASE_SOUSCRIPTEURS!$K$5:$K$14) -> 510255.4 | G26: =IF(C26=0,0,E26/C26*1000) -> 5.2181857 | H26: =IF(DASHBOARD!D27=0,0,D26/DASHBOARD!D27) -> 0.17187531
A27: TOTAL | C27: =SUM(C21:C26) -> 116000000 | D27: =SUM(D21:D26) -> 2968753.4 | E27: =SUM(E21:E26) -> 330300.61 | F27: =SUM(F21:F26) -> 2968753.4 | G27: =AVERAGE(G21:G26) -> 4.3101066 | H27: 100%

Sheet PARAMETRES
A2: SIMULATEUR DÉCÈS EMPRUNTEUR — MULTI-TÊTES
A3: Paramètres Actuariels & Hypothèses de Tarification • FCFA • Table CIMA
A5: A — Hypothèses financières
A6: Paramètre | B6: Valeur | C6: Unité / Remarque | D6: Ref.
A7: Taux technique (i) | B7: 0.035 | C7: 3,500% | D7: i
A8: Taux d'intérêt prêt (r) | B8: 0.035 | C8: 3,500% | D8: r
A9: Devise | B9: FCFA | C9: — | D9: —
A11: B — Chargements (% de la prime pure)
A12: Type de chargement | B12: Taux | C12: Description | D12: Ref.
A13: Acquisition (α) | B13: 0.1 | C13: Frais de mise en place | D13: α
A14: Gestion (β) | B14: 0.03 | C14: Frais annuels de gestion | D14: β
A15: Marge commerciale (γ) | B15: 0.1 | C15: Profit technique | D15: γ
A17: C — Table de mortalité CIMA H (applicable tous sexes — règle zone CIMA)
A18: Âge (x) | B18: q_x CIMA H (tous sexes) | C18: Source | D18: Remarque
A19: 18 | B19: =IFERROR(VLOOKUP(18,'CIMA_H (décès)'!$A$1:$C$112,3,FALSE()),"—") -> 0.0013370022 | C19: CIMA_H (décès) | D19: Tous sexes — règle CIMA
A20: 20 | B20: =IFERROR(VLOOKUP(20,'CIMA_H (décès)'!$A$1:$C$112,3,FALSE()),"—") -> 0.0015776776 | C20: CIMA_H (décès)
A21: 25 | B21: =IFERROR(VLOOKUP(25,'CIMA_H (décès)'!$A$1:$C$112,3,FALSE()),"—") -> 0.0017528946 | C21: CIMA_H (décès)
A22: 30 | B22: =IFERROR(VLOOKUP(30,'CIMA_H (décès)'!$A$1:$C$112,3,FALSE()),"—") -> 0.0019934237 | C22: CIMA_H (décès)
A23: 35 | B23: =IFERROR(VLOOKUP(35,'CIMA_H (décès)'!$A$1:$C$112,3,FALSE()),"—") -> 0.0024774917 | C23: CIMA_H (décès)
A24: 40 | B24: =IFERROR(VLOOKUP(40,'CIMA_H (décès)'!$A$1:$C$112,3,FALSE()),"—") -> 0.0034965982 | C24: CIMA_H (décès)
A25: 45 | B25: =IFERROR(VLOOKUP(45,'CIMA_H (décès)'!$A$1:$C$112,3,FALSE()),"—") -> 0.0052712427 | C25: CIMA_H (décès)
A26: 50 | B26: =IFERROR(VLOOKUP(50,'CIMA_H (décès)'!$A$1:$C$112,3,FALSE()),"—") -> 0.0071410225 | C26: CIMA_H (décès)
A27: 55 | B27: =IFERROR(VLOOKUP(55,'CIMA_H (décès)'!$A$1:$C$112,3,FALSE()),"—") -> 0.0093751265 | C27: CIMA_H (décès)
A28: 60 | B28: =IFERROR(VLOOKUP(60,'CIMA_H (décès)'!$A$1:$C$112,3,FALSE()),"—") -> 0.013525922 | C28: CIMA_H (décès)
A29: 65 | B29: =IFERROR(VLOOKUP(65,'CIMA_H (décès)'!$A$1:$C$112,3,FALSE()),"—") -> 0.020784241 | C29: CIMA_H (décès)
A30: 70 | B30: =IFERROR(VLOOKUP(70,'CIMA_H (décès)'!$A$1:$C$112,3,FALSE()),"—") -> 0.029820113 | C30: CIMA_H (décès)
A31: 75 | B31: =IFERROR(VLOOKUP(75,'CIMA_H (décès)'!$A$1:$C$112,3,FALSE()),"—") -> 0.042415206 | C31: CIMA_H (décès)
A32: 80 | B32: =IFERROR(VLOOKUP(80,'CIMA_H (décès)'!$A$1:$C$112,3,FALSE()),"—") -> 0.062563454 | C32: CIMA_H (décès)
A33: 85 | B33: =IFERROR(VLOOKUP(85,'CIMA_H (décès)'!$A$1:$C$112,3,FALSE()),"—") -> 0.096665051 | C33: CIMA_H (décès)
A34: 90 | B34: =IFERROR(VLOOKUP(90,'CIMA_H (décès)'!$A$1:$C$112,3,FALSE()),"—") -> 0.14225467 | C34: CIMA_H (décès)

Sheet BASE_SOUSCRIPTEURS
A2: BASE DES SOUSCRIPTEURS — DÉCÈS EMPRUNTEUR MULTI-TÊTES
A3: Saisir un assuré par ligne • Les colonnes grisées sont calculées automatiquement • Montants en FCFA
A4: N° Contrat | B4: Nom Assuré | C4: Sexe (H/F) | D4: Âge (ans) | E4: Durée (années) | F4: Capital (FCFA) | G4: Quotité (%) | H4: CRD Actuel (FCFA) | I4: q_x (CIMA H tous sexes) | J4: ä_(x,n) | K4: PP (FCFA) | L4: PA (FCFA/an) | M4: PI (FCFA/an) | N4: PC (FCFA/an)
A5: CTR-001 | B5: DIALLO Mamadou | C5: H | D5: 40 | E5: 20 | F5: 15000000 | G5: 0.6 | H5: =F5 -> 15000000 | I5: =IFERROR(VLOOKUP(MIN(D5,105),'CIMA_H (décès)'!$A$1:$C$112,3,FALSE()),1) -> 0.0034965982 | J5: =IF(OR(D5="",E5=""),0,(1-(1-I5)^E5*(1/(1+PARAMETRES!$B$7))^E5)/(I5+PARAMETRES!$B$7)) -> 13.804758 | K5: =IF(OR(F5=0,E5=0),0,(I5/(I5+PARAMETRES!$B$7))*F5*G5*(1-((1/(1+PARAMETRES!$B$7))*(1-I5))^E5)) -> 434427.23 | L5: =IF(J5=0,0,K5/J5) -> 31469.384 | M5: =IF(J5=0,0,K5*(1+PARAMETRES!$B$13+PARAMETRES!$B$14)/J5) -> 35560.404 | N5: =IF(J5=0,0,K5*(1+PARAMETRES!$B$13+PARAMETRES!$B$14+PARAMETRES!$B$15)/J5) -> 38707.343
A6: CTR-001 | B6: DIALLO Aminata | C6: F | D6: 35 | E6: 20 | F6: 15000000 | G6: 0.4 | H6: =F6 -> 15000000 | I6: =IFERROR(VLOOKUP(MIN(D6,105),'CIMA_H (décès)'!$A$1:$C$112,3,FALSE()),1) -> 0.0024774917 | J6: =IF(OR(D6="",E6=""),0,(1-(1-I6)^E6*(1/(1+PARAMETRES!$B$7))^E6)/(I6+PARAMETRES!$B$7)) -> 13.921921 | K6: =IF(OR(F6=0,E6=0),0,(I6/(I6+PARAMETRES!$B$7))*F6*G6*(1-((1/(1+PARAMETRES!$B$7))*(1-I6))^E6)) -> 206948.67 | L6: =IF(J6=0,0,K6/J6) -> 14864.95 | M6: =IF(J6=0,0,K6*(1+PARAMETRES!$B$13+PARAMETRES!$B$14)/J6) -> 16797.394 | N6: =IF(J6=0,0,K6*(1+PARAMETRES!$B$13+PARAMETRES!$B$14+PARAMETRES!$B$15)/J6) -> 18283.889
A7: CTR-002 | B7: SALL Ibrahim | C7: H | D7: 45 | E7: 15 | F7: 10000000 | G7: 1 | H7: =F7 -> 10000000 | I7: =IFERROR(VLOOKUP(MIN(D7,105),'CIMA_H (décès)'!$A$1:$C$112,3,FALSE()),1) -> 0.0052712427 | J7: =IF(OR(D7="",E7=""),0,(1-(1-I7)^E7*(1/(1+PARAMETRES!$B$7))^E7)/(I7+PARAMETRES!$B$7)) -> 11.139523 | K7: =IF(OR(F7=0,E7=0),0,(I7/(I7+PARAMETRES!$B$7))*F7*G7*(1-((1/(1+PARAMETRES!$B$7))*(1-I7))^E7)) -> 587191.27 | L7: =IF(J7=0,0,K7/J7) -> 52712.427 | M7: =IF(J7=0,0,K7*(1+PARAMETRES!$B$13+PARAMETRES!$B$14)/J7) -> 59565.042 | N7: =IF(J7=0,0,K7*(1+PARAMETRES!$B$13+PARAMETRES!$B$14+PARAMETRES!$B$15)/J7) -> 64836.285
A8: CTR-003 | B8: NDIAYE Fatou | C8: F | D8: 38 | E8: 12 | F8: 8000000 | G8: 0.5 | H8: =F8 -> 8000000 | I8: =IFERROR(VLOOKUP(MIN(D8,105),'CIMA_H (décès)'!$A$1:$C$112,3,FALSE()),1) -> 0.0030035109 | J8: =IF(OR(D8="",E8=""),0,(1-(1-I8)^E8*(1/(1+PARAMETRES!$B$7))^E8)/(I8+PARAMETRES!$B$7)) -> 9.5169807 | K8: =IF(OR(F8=0,E8=0),0,(I8/(I8+PARAMETRES!$B$7))*F8*G8*(1-((1/(1+PARAMETRES!$B$7))*(1-I8))^E8)) -> 114337.42 | L8: =IF(J8=0,0,K8/J8) -> 12014.044 | M8: =IF(J8=0,0,K8*(1+PARAMETRES!$B$13+PARAMETRES!$B$14)/J8) -> 13575.869 | N8: =IF(J8=0,0,K8*(1+PARAMETRES!$B$13+PARAMETRES!$B$14+PARAMETRES!$B$15)/J8) -> 14777.274
A9: CTR-003 | B9: NDIAYE Ousmane | C9: H | D9: 42 | E9: 12 | F9: 8000000 | G9: 0.5 | H9: =F9 -> 8000000 | I9: =IFERROR(VLOOKUP(MIN(D9,105),'CIMA_H (décès)'!$A$1:$C$112,3,FALSE()),1) -> 0.0041432871 | J9: =IF(OR(D9="",E9=""),0,(1-(1-I9)^E9*(1/(1+PARAMETRES!$B$7))^E9)/(I9+PARAMETRES!$B$7)) -> 9.4621755 | K9: =IF(OR(F9=0,E9=0),0,(I9/(I9+PARAMETRES!$B$7))*F9*G9*(1-((1/(1+PARAMETRES!$B$7))*(1-I9))^E9)) -> 156818.04 | L9: =IF(J9=0,0,K9/J9) -> 16573.148 | M9: =IF(J9=0,0,K9*(1+PARAMETRES!$B$13+PARAMETRES!$B$14)/J9) -> 18727.658 | N9: =IF(J9=0,0,K9*(1+PARAMETRES!$B$13+PARAMETRES!$B$14+PARAMETRES!$B$15)/J9) -> 20384.973
A10: CTR-004 | B10: TOURE Aissatou | C10: F | D10: 30 | E10: 25 | F10: 20000000 | G10: 0.6 | H10: =F10 -> 20000000 | I10: =IFERROR(VLOOKUP(MIN(D10,105),'CIMA_H (décès)'!$A$1:$C$112,3,FALSE()),1) -> 0.0019934237 | J10: =IF(OR(D10="",E10=""),0,(1-(1-I10)^E10*(1/(1+PARAMETRES!$B$7))^E10)/(I10+PARAMETRES!$B$7)) -> 16.150005 | K10: =IF(OR(F10=0,E10=0),0,(I10/(I10+PARAMETRES!$B$7))*F10*G10*(1-((1/(1+PARAMETRES!$B$7))*(1-I10))^E10)) -> 386325.62 | L10: =IF(J10=0,0,K10/J10) -> 23921.084 | M10: =IF(J10=0,0,K10*(1+PARAMETRES!$B$13+PARAMETRES!$B$14)/J10) -> 27030.825 | N10: =IF(J10=0,0,K10*(1+PARAMETRES!$B$13+PARAMETRES!$B$14+PARAMETRES!$B$15)/J10) -> 29422.933
A11: CTR-004 | B11: TOURE Boubacar | C11: H | D11: 33 | E11: 25 | F11: 20000000 | G11: 0.4 | H11: =F11 -> 20000000 | I11: =IFERROR(VLOOKUP(MIN(D11,105),'CIMA_H (décès)'!$A$1:$C$112,3,FALSE()),1) -> 0.002205065 | J11: =IF(OR(D11="",E11=""),0,(1-(1-I11)^E11*(1/(1+PARAMETRES!$B$7))^E11)/(I11+PARAMETRES!$B$7)) -> 16.115353 | K11: =IF(OR(F11=0,E11=0),0,(I11/(I11+PARAMETRES!$B$7))*F11*G11*(1-((1/(1+PARAMETRES!$B$7))*(1-I11))^E11)) -> 284283.2 | L11: =IF(J11=0,0,K11/J11) -> 17640.52 | M11: =IF(J11=0,0,K11*(1+PARAMETRES!$B$13+PARAMETRES!$B$14)/J11) -> 19933.788 | N11: =IF(J11=0,0,K11*(1+PARAMETRES!$B$13+PARAMETRES!$B$14+PARAMETRES!$B$15)/J11) -> 21697.84
A12: CTR-005 | B12: BARRY Mariama | C12: F | D12: 50 | E12: 10 | F12: 5000000 | G12: 1 | H12: =F12 -> 5000000 | I12: =IFERROR(VLOOKUP(MIN(D12,105),'CIMA_H (décès)'!$A$1:$C$112,3,FALSE()),1) -> 0.0071410225 | J12: =IF(OR(D12="",E12=""),0,(1-(1-I12)^E12*(1/(1+PARAMETRES!$B$7))^E12)/(I12+PARAMETRES!$B$7)) -> 8.0707356 | K12: =IF(OR(F12=0,E12=0),0,(I12/(I12+PARAMETRES!$B$7))*F12*G12*(1-((1/(1+PARAMETRES!$B$7))*(1-I12))^E12)) -> 288166.52 | L12: =IF(J12=0,0,K12/J12) -> 35705.112 | M12: =IF(J12=0,0,K12*(1+PARAMETRES!$B$13+PARAMETRES!$B$14)/J12) -> 40346.777 | N12: =IF(J12=0,0,K12*(1+PARAMETRES!$B$13+PARAMETRES!$B$14+PARAMETRES!$B$15)/J12) -> 43917.288
A13: CTR-006 | B13: CAMARA Seydou | C13: H | D13: 55 | E13: 10 | F13: 7500000 | G13: 0.7 | H13: =F13 -> 7500000 | I13: =IFERROR(VLOOKUP(MIN(D13,105),'CIMA_H (décès)'!$A$1:$C$112,3,FALSE()),1) -> 0.0093751265 | J13: =IF(OR(D13="",E13=""),0,(1-(1-I13)^E13*(1/(1+PARAMETRES!$B$7))^E13)/(I13+PARAMETRES!$B$7)) -> 7.9956567 | K13: =IF(OR(F13=0,E13=0),0,(I13/(I13+PARAMETRES!$B$7))*F13*G13*(1-((1/(1+PARAMETRES!$B$7))*(1-I13))^E13)) -> 393541.54 | L13: =IF(J13=0,0,K13/J13) -> 49219.414 | M13: =IF(J13=0,0,K13*(1+PARAMETRES!$B$13+PARAMETRES!$B$14)/J13) -> 55617.938 | N13: =IF(J13=0,0,K13*(1+PARAMETRES!$B$13+PARAMETRES!$B$14+PARAMETRES!$B$15)/J13) -> 60539.879
A14: CTR-006 | B14: CAMARA Kadiatou | C14: F | D14: 48 | E14: 10 | F14: 7500000 | G14: 0.3 | H14: =F14 -> 7500000 | I14: =IFERROR(VLOOKUP(MIN(D14,105),'CIMA_H (décès)'!$A$1:$C$112,3,FALSE()),1) -> 0.0064075543 | J14: =IF(OR(D14="",E14=""),0,(1-(1-I14)^E14*(1/(1+PARAMETRES!$B$7))^E14)/(I14+PARAMETRES!$B$7)) -> 8.0955737 | K14: =IF(OR(F14=0,E14=0),0,(I14/(I14+PARAMETRES!$B$7))*F14*G14*(1-((1/(1+PARAMETRES!$B$7))*(1-I14))^E14)) -> 116713.86 | L14: =IF(J14=0,0,K14/J14) -> 14416.997 | M14: =IF(J14=0,0,K14*(1+PARAMETRES!$B$13+PARAMETRES!$B$14)/J14) -> 16291.207 | N14: =IF(J14=0,0,K14*(1+PARAMETRES!$B$13+PARAMETRES!$B$14+PARAMETRES!$B$15)/J14) -> 17732.906
A15: TOTAUX | F15: =SUM(F5:F14) -> 116000000 | H15: =SUM(H5:H14) -> 116000000 | I15: =IFERROR(VLOOKUP(MIN(D15,105),'CIMA_H (décès)'!$A$1:$C$112,3,FALSE()),1) -> 1 | J15: =IF(OR(D15="",E15=""),0,(1-(1-I15)^E15*(1/(1+PARAMETRES!$B$7))^E15)/(I15+PARAMETRES!$B$7)) -> 0 | K15: =IF(OR(F15=0,E15=0),0,(I15/(I15+PARAMETRES!$B$7))*F15*G15*(1-((1/(1+PARAMETRES!$B$7))*(1-I15))^E15)) -> 0 | L15: =IF(J15=0,0,K15/J15) -> 0 | M15: =IF(J15=0,0,K15*(1+PARAMETRES!$B$13+PARAMETRES!$B$14)/J15) -> 0 | N15: =IF(J15=0,0,K15*(1+PARAMETRES!$B$13+PARAMETRES!$B$14+PARAMETRES!$B$15)/J15) -> 0

Sheet TABLEAU_PRIMES
A2: TABLEAU RÉCAPITULATIF DES PRIMES PAR CONTRAT — FCFA
A3: N° Contrat | B3: Nom Assuré | C3: Sexe | D3: PP (FCFA) | E3: PA (FCFA/an) | F3: PI (FCFA/an) | G3: PC (FCFA/an) | H3: Taux PC (‰ capital) | I3: PM Init. (FCFA) | J3: Quotité
A4: =BASE_SOUSCRIPTEURS!A5 -> CTR-001 | B4: =BASE_SOUSCRIPTEURS!B5 -> DIALLO Mamadou | C4: =BASE_SOUSCRIPTEURS!C5 -> H | D4: =BASE_SOUSCRIPTEURS!K5 -> 434427.23 | E4: =BASE_SOUSCRIPTEURS!L5 -> 31469.384 | F4: =BASE_SOUSCRIPTEURS!M5 -> 35560.404 | G4: =BASE_SOUSCRIPTEURS!N5 -> 38707.343 | H4: =IF(BASE_SOUSCRIPTEURS!F5=0,0,BASE_SOUSCRIPTEURS!N5/BASE_SOUSCRIPTEURS!F5*1000) -> 2.5804895 | I4: =BASE_SOUSCRIPTEURS!K5 -> 434427.23 | J4: =BASE_SOUSCRIPTEURS!G5 -> 0.6
A5: =BASE_SOUSCRIPTEURS!A6 -> CTR-001 | B5: =BASE_SOUSCRIPTEURS!B6 -> DIALLO Aminata | C5: =BASE_SOUSCRIPTEURS!C6 -> F | D5: =BASE_SOUSCRIPTEURS!K6 -> 206948.67 | E5: =BASE_SOUSCRIPTEURS!L6 -> 14864.95 | F5: =BASE_SOUSCRIPTEURS!M6 -> 16797.394 | G5: =BASE_SOUSCRIPTEURS!N6 -> 18283.889 | H5: =IF(BASE_SOUSCRIPTEURS!F6=0,0,BASE_SOUSCRIPTEURS!N6/BASE_SOUSCRIPTEURS!F6*1000) -> 1.2189259 | I5: =BASE_SOUSCRIPTEURS!K6 -> 206948.67 | J5: =BASE_SOUSCRIPTEURS!G6 -> 0.4
A6: =BASE_SOUSCRIPTEURS!A7 -> CTR-002 | B6: =BASE_SOUSCRIPTEURS!B7 -> SALL Ibrahim | C6: =BASE_SOUSCRIPTEURS!C7 -> H | D6: =BASE_SOUSCRIPTEURS!K7 -> 587191.27 | E6: =BASE_SOUSCRIPTEURS!L7 -> 52712.427 | F6: =BASE_SOUSCRIPTEURS!M7 -> 59565.042 | G6: =BASE_SOUSCRIPTEURS!N7 -> 64836.285 | H6: =IF(BASE_SOUSCRIPTEURS!F7=0,0,BASE_SOUSCRIPTEURS!N7/BASE_SOUSCRIPTEURS!F7*1000) -> 6.4836285 | I6: =BASE_SOUSCRIPTEURS!K7 -> 587191.27 | J6: =BASE_SOUSCRIPTEURS!G7 -> 1
A7: =BASE_SOUSCRIPTEURS!A8 -> CTR-003 | B7: =BASE_SOUSCRIPTEURS!B8 -> NDIAYE Fatou | C7: =BASE_SOUSCRIPTEURS!C8 -> F | D7: =BASE_SOUSCRIPTEURS!K8 -> 114337.42 | E7: =BASE_SOUSCRIPTEURS!L8 -> 12014.044 | F7: =BASE_SOUSCRIPTEURS!M8 -> 13575.869 | G7: =BASE_SOUSCRIPTEURS!N8 -> 14777.274 | H7: =IF(BASE_SOUSCRIPTEURS!F8=0,0,BASE_SOUSCRIPTEURS!N8/BASE_SOUSCRIPTEURS!F8*1000) -> 1.8471592 | I7: =BASE_SOUSCRIPTEURS!K8 -> 114337.42 | J7: =BASE_SOUSCRIPTEURS!G8 -> 0.5
A8: =BASE_SOUSCRIPTEURS!A9 -> CTR-003 | B8: =BASE_SOUSCRIPTEURS!B9 -> NDIAYE Ousmane | C8: =BASE_SOUSCRIPTEURS!C9 -> H | D8: =BASE_SOUSCRIPTEURS!K9 -> 156818.04 | E8: =BASE_SOUSCRIPTEURS!L9 -> 16573.148 | F8: =BASE_SOUSCRIPTEURS!M9 -> 18727.658 | G8: =BASE_SOUSCRIPTEURS!N9 -> 20384.973 | H8: =IF(BASE_SOUSCRIPTEURS!F9=0,0,BASE_SOUSCRIPTEURS!N9/BASE_SOUSCRIPTEURS!F9*1000) -> 2.5481216 | I8: =BASE_SOUSCRIPTEURS!K9 -> 156818.04 | J8: =BASE_SOUSCRIPTEURS!G9 -> 0.5
A9: =BASE_SOUSCRIPTEURS!A10 -> CTR-004 | B9: =BASE_SOUSCRIPTEURS!B10 -> TOURE Aissatou | C9: =BASE_SOUSCRIPTEURS!C10 -> F | D9: =BASE_SOUSCRIPTEURS!K10 -> 386325.62 | E9: =BASE_SOUSCRIPTEURS!L10 -> 23921.084 | F9: =BASE_SOUSCRIPTEURS!M10 -> 27030.825 | G9: =BASE_SOUSCRIPTEURS!N10 -> 29422.933 | H9: =IF(BASE_SOUSCRIPTEURS!F10=0,0,BASE_SOUSCRIPTEURS!N10/BASE_SOUSCRIPTEURS!F10*1000) -> 1.4711467 | I9: =BASE_SOUSCRIPTEURS!K10 -> 386325.62 | J9: =BASE_SOUSCRIPTEURS!G10 -> 0.6
A10: =BASE_SOUSCRIPTEURS!A11 -> CTR-004 | B10: =BASE_SOUSCRIPTEURS!B11 -> TOURE Boubacar | C10: =BASE_SOUSCRIPTEURS!C11 -> H | D10: =BASE_SOUSCRIPTEURS!K11 -> 284283.2 | E10: =BASE_SOUSCRIPTEURS!L11 -> 17640.52 | F10: =BASE_SOUSCRIPTEURS!M11 -> 19933.788 | G10: =BASE_SOUSCRIPTEURS!N11 -> 21697.84 | H10: =IF(BASE_SOUSCRIPTEURS!F11=0,0,BASE_SOUSCRIPTEURS!N11/BASE_SOUSCRIPTEURS!F11*1000) -> 1.084892 | I10: =BASE_SOUSCRIPTEURS!K11 -> 284283.2 | J10: =BASE_SOUSCRIPTEURS!G11 -> 0.4
A11: =BASE_SOUSCRIPTEURS!A12 -> CTR-005 | B11: =BASE_SOUSCRIPTEURS!B12 -> BARRY Mariama | C11: =BASE_SOUSCRIPTEURS!C12 -> F | D11: =BASE_SOUSCRIPTEURS!K12 -> 288166.52 | E11: =BASE_SOUSCRIPTEURS!L12 -> 35705.112 | F11: =BASE_SOUSCRIPTEURS!M12 -> 40346.777 | G11: =BASE_SOUSCRIPTEURS!N12 -> 43917.288 | H11: =IF(BASE_SOUSCRIPTEURS!F12=0,0,BASE_SOUSCRIPTEURS!N12/BASE_SOUSCRIPTEURS!F12*1000) -> 8.7834577 | I11: =BASE_SOUSCRIPTEURS!K12 -> 288166.52 | J11: =BASE_SOUSCRIPTEURS!G12 -> 1
A12: =BASE_SOUSCRIPTEURS!A13 -> CTR-006 | B12: =BASE_SOUSCRIPTEURS!B13 -> CAMARA Seydou | C12: =BASE_SOUSCRIPTEURS!C13 -> H | D12: =BASE_SOUSCRIPTEURS!K13 -> 393541.54 | E12: =BASE_SOUSCRIPTEURS!L13 -> 49219.414 | F12: =BASE_SOUSCRIPTEURS!M13 -> 55617.938 | G12: =BASE_SOUSCRIPTEURS!N13 -> 60539.879 | H12: =IF(BASE_SOUSCRIPTEURS!F13=0,0,BASE_SOUSCRIPTEURS!N13/BASE_SOUSCRIPTEURS!F13*1000) -> 8.0719839 | I12: =BASE_SOUSCRIPTEURS!K13 -> 393541.54 | J12: =BASE_SOUSCRIPTEURS!G13 -> 0.7
A13: =BASE_SOUSCRIPTEURS!A14 -> CTR-006 | B13: =BASE_SOUSCRIPTEURS!B14 -> CAMARA Kadiatou | C13: =BASE_SOUSCRIPTEURS!C14 -> F | D13: =BASE_SOUSCRIPTEURS!K14 -> 116713.86 | E13: =BASE_SOUSCRIPTEURS!L14 -> 14416.997 | F13: =BASE_SOUSCRIPTEURS!M14 -> 16291.207 | G13: =BASE_SOUSCRIPTEURS!N14 -> 17732.906 | H13: =IF(BASE_SOUSCRIPTEURS!F14=0,0,BASE_SOUSCRIPTEURS!N14/BASE_SOUSCRIPTEURS!F14*1000) -> 2.3643875 | I13: =BASE_SOUSCRIPTEURS!K14 -> 116713.86 | J13: =BASE_SOUSCRIPTEURS!G14 -> 0.3
A14: TOTAL PORTEFEUILLE | D14: =SUM(D4:D13) -> 2968753.4 | E14: =SUM(E4:E13) -> 268537.08 | F14: =SUM(F4:F13) -> 303446.9 | G14: =SUM(G4:G13) -> 330300.61 | H14: =AVERAGE(H4:H13) -> 3.6454192 | I14: =SUM(I4:I13) -> 2968753.4

Sheet AMORTISSEMENT_CRD
A2: TABLEAU D'AMORTISSEMENT & CRD — CALCUL AUTOMATIQUE PAR CONTRAT
A3: ▶ Sélectionner un assuré : | D3: N° Contrat | E3: CTR-001 | F3: Assuré (ligne BASE) | G3: 5 | I3: =G3 -> 5
A5: Nom | B5: =INDEX(BASE_SOUSCRIPTEURS!B:B,I3) -> DIALLO Mamadou
A6: Sexe | B6: =INDEX(BASE_SOUSCRIPTEURS!C:C,I3) -> H
A7: Âge | B7: =INDEX(BASE_SOUSCRIPTEURS!D:D,I3) -> 40
A8: Durée | B8: =INDEX(BASE_SOUSCRIPTEURS!E:E,I3) -> 20
A9: Capital (FCFA) | B9: =INDEX(BASE_SOUSCRIPTEURS!F:F,I3) -> 15000000
A10: Quotité | B10: =INDEX(BASE_SOUSCRIPTEURS!G:G,I3) -> 0.6
A11: Taux prêt | B11: =PARAMETRES!B8 -> 0.035
A13: Année t | B13: Annuité (FCFA) | C13: Intérêts (FCFA) | D13: Amort. (FCFA) | E13: CRD (FCFA) | F13: q_(x+t) CIMA | G13: ₜpₓ | H13: PP annuelle (FCFA) | I13: PM (FCFA)
A14: 1 | B14: =IF(1<=INDEX(BASE_SOUSCRIPTEURS!E:E,$I$3),INDEX(BASE_SOUSCRIPTEURS!F:F,$I$3)*PARAMETRES!$B$8*(1+PARAMETRES!$B$8)^INDEX(BASE_SOUSCRIPTEURS!E:E,$I$3)/((1+PARAMETRES!$B$8)^INDEX(BASE_SOUSCRIPTEURS!E:E,$I$3)-1),0) -> 1055416.2 | C14: =IF(1<=INDEX(BASE_SOUSCRIPTEURS!E:E,$I$3),INDEX(BASE_SOUSCRIPTEURS!F:F,$I$3)*PARAMETRES!$B$8,0) -> 525000 | D14: =IF(1<=INDEX(BASE_SOUSCRIPTEURS!E:E,$I$3),B14-C14,0) -> 530416.15 | E14: =IF(1<=INDEX(BASE_SOUSCRIPTEURS!E:E,$I$3),INDEX(BASE_SOUSCRIPTEURS!F:F,$I$3)-D14,0) -> 14469584 | F14: =IF(1>INDEX(BASE_SOUSCRIPTEURS!E:E,$I$3),0,IFERROR(VLOOKUP(MIN((INDEX(BASE_SOUSCRIPTEURS!D:D,$I$3)+0),105),'CIMA_H (décès)'!$A$1:$C$112,3,FALSE()),1)) -> 0.0034965982 | G14: =IF(1<=INDEX(BASE_SOUSCRIPTEURS!E:E,$I$3),1-F14,0) -> 0.9965034 | H14: =IF(1<=INDEX(BASE_SOUSCRIPTEURS!E:E,$I$3),(1/(1+PARAMETRES!$B$7))^1*1*F14*E14*INDEX(BASE_SOUSCRIPTEURS!G:G,$I$3),0) -> 29330.041 | I14: =IF(1<=INDEX(BASE_SOUSCRIPTEURS!E:E,$I$3),SUM(H14:H43),0) -> 379040.24
A15: 2 | B15: =IF(2<=INDEX(BASE_SOUSCRIPTEURS!E:E,$I$3),INDEX(BASE_SOUSCRIPTEURS!F:F,$I$3)*PARAMETRES!$B$8*(1+PARAMETRES!$B$8)^INDEX(BASE_SOUSCRIPTEURS!E:E,$I$3)/((1+PARAMETRES!$B$8)^INDEX(BASE_SOUSCRIPTEURS!E:E,$I$3)-1),0) -> 1055416.2 | C15: =IF(2<=INDEX(BASE_SOUSCRIPTEURS!E:E,$I$3),E14*PARAMETRES!$B$8,0) -> 506435.43 | D15: =IF(2<=INDEX(BASE_SOUSCRIPTEURS!E:E,$I$3),B15-C15,0) -> 548980.72 | E15: =IF(2<=INDEX(BASE_SOUSCRIPTEURS!E:E,$I$3),E14-D15,0) -> 13920603 | F15: =IF(2>INDEX(BASE_SOUSCRIPTEURS!E:E,$I$3),0,IFERROR(VLOOKUP(MIN((INDEX(BASE_SOUSCRIPTEURS!D:D,$I$3)+1),105),'CIMA_H (décès)'!$A$1:$C$112,3,FALSE()),1)) -> 0.0038163495 | G15: =IF(2<=INDEX(BASE_SOUSCRIPTEURS!E:E,$I$3),G14*(1-F15),0) -> 0.9927004 | H15: =IF(2<=INDEX(BASE_SOUSCRIPTEURS!E:E,$I$3),(1/(1+PARAMETRES!$B$7))^2*G14*F14*E15*INDEX(BASE_SOUSCRIPTEURS!G:G,$I$3),0) -> 27167.716 | I15: =IF(2<=INDEX(BASE_SOUSCRIPTEURS!E:E,$I$3),SUM(H15:H43),0) -> 349710.2
A16: 3 | B16: =IF(3<=INDEX(BASE_SOUSCRIPTEURS!E:E,$I$3),INDEX(BASE_SOUSCRIPTEURS!F:F,$I$3)*PARAMETRES!$B$8*(1+PARAMETRES!$B$8)^INDEX(BASE_SOUSCRIPTEURS!E:E,$I$3)/((1+PARAMETRES!$B$8)^INDEX(BASE_SOUSCRIPTEURS!E:E,$I$3)-1),0) -> 1055416.2 | C16: =IF(3<=INDEX(BASE_SOUSCRIPTEURS!E:E,$I$3),E15*PARAMETRES!$B$8,0) -> 487221.11 | D16: =IF(3<=INDEX(BASE_SOUSCRIPTEURS!E:E,$I$3),B16-C16,0) -> 568195.04 | E16: =IF(3<=INDEX(BASE_SOUSCRIPTEURS!E:E,$I$3),E15-D16,0) -> 13352408 | F16: =IF(3>INDEX(BASE_SOUSCRIPTEURS!E:E,$I$3),0,IFERROR(VLOOKUP(MIN((INDEX(BASE_SOUSCRIPTEURS!D:D,$I$3)+2),105),'CIMA_H (décès)'!$A$1:$C$112,3,FALSE()),1)) -> 0.0041432871 | G16: =IF(3<=INDEX(BASE_SOUSCRIPTEURS!E:E,$I$3),G15*(1-F16),0) -> 0.98858735 | H16: =IF(3<=INDEX(BASE_SOUSCRIPTEURS!E:E,$I$3),(1/(1+PARAMETRES!$B$7))^3*G15*F15*E16*INDEX(BASE_SOUSCRIPTEURS!G:G,$I$3),0) -> 27375.126 | I16: =IF(3<=INDEX(BASE_SOUSCRIPTEURS!E:E,$I$3),SUM(H16:H43),0) -> 322542.48
A17: 4 | B17: =IF(4<=INDEX(BASE_SOUSCRIPTEURS!E:E,$I$3),INDEX(BASE_SOUSCRIPTEURS!F:F,$I$3)*PARAMETRES!$B$8*(1+PARAMETRES!$B$8)^INDEX(BASE_SOUSCRIPTEURS!E:E,$I$3)/((1+PARAMETRES!$B$8)^INDEX(BASE_SOUSCRIPTEURS!E:E,$I$3)-1),0) -> 1055416.2 | C17: =IF(4<=INDEX(BASE_SOUSCRIPTEURS!E:E,$I$3),E16*PARAMETRES!$B$8,0) -> 467334.28 | D17: =IF(4<=INDEX(BASE_SOUSCRIPTEURS!E:E,$I$3),B17-C17,0) -> 588081.87 | E17: =IF(4<=INDEX(BASE_SOUSCRIPTEURS!E:E,$I$3),E16-D17,0) -> 12764326 | F17: =IF(4>INDEX(BASE_SOUSCRIPTEURS!E:E,$I$3),0,IFERROR(VLOOKUP(MIN((INDEX(BASE_SOUSCRIPTEURS!D:D,$I$3)+3),105),'CIMA_H (décès)'!$A$1:$C$112,3,FALSE()),1)) -> 0.0045007439 | G17: =IF(4<=INDEX(BASE_SOUSCRIPTEURS!E:E,$I$3),G16*(1-F17),0) -> 0.98413798 | H17: =IF(4<=INDEX(BASE_SOUSCRIPTEURS!E:E,$I$3),(1/(1+PARAMETRES!$B$7))^4*G16*F16*E17*INDEX(BASE_SOUSCRIPTEURS!G:G,$I$3),0) -> 27336.809 | I17: =IF(4<=INDEX(BASE_SOUSCRIPTEURS!E:E,$I$3),SUM(H17:H43),0) -> 295167.36
A18: 5 | B18: =IF(5<=INDEX(BASE_SOUSCRIPTEURS!E:E,$I$3),INDEX(BASE_SOUSCRIPTEURS!F:F,$I$3)*PARAMETRES!$B$8*(1+PARAMETRES!$B$8)^INDEX(BASE_SOUSCRIPTEURS!E:E,$I$3)/((1+PARAMETRES!$B$8)^INDEX(BASE_SOUSCRIPTEURS!E:E,$I$3)-1),0) -> 1055416.2 | C18: =IF(5<=INDEX(BASE_SOUSCRIPTEURS!E:E,$I$3),E17*PARAMETRES!$B$8,0) -> 446751.42 | D18: =IF(5<=INDEX(BASE_SOUSCRIPTEURS!E:E,$I$3),B18-C18,0) -> 608664.73 | E18: =IF(5<=INDEX(BASE_SOUSCRIPTEURS!E:E,$I$3),E17-D18,0) -> 12155661 | F18: =IF(5>INDEX(BASE_SOUSCRIPTEURS!E:E,$I$3),0,IFERROR(VLOOKUP(MIN((INDEX(BASE_SOUSCRIPTEURS!D:D,$I$3)+4),105),'CIMA_H (décès)'!$A$1:$C$112,3,FALSE()),1)) -> 0.0048767277 | G18: =IF(5<=INDEX(BASE_SOUSCRIPTEURS!E:E,$I$3),G17*(1-F18),0) -> 0.9793386 | H18: =IF(5<=INDEX(BASE_SOUSCRIPTEURS!E:E,$I$3),(1/(1+PARAMETRES!$B$7))^5*G17*F17*E18*INDEX(BASE_SOUSCRIPTEURS!G:G,$I$3),0) -> 27199.968 | I18: =IF(5<=INDEX(BASE_SOUSCRIPTEURS!E:E,$I$3),SUM(H18:H43),0) -> 267830.55
A19: 6 | B19: =IF(6<=INDEX(BASE_SOUSCRIPTEURS!E:E,$I$3),INDEX(BASE_SOUSCRIPTEURS!F:F,$I$3)*PARAMETRES!$B$8*(1+PARAMETRES!$B$8)^INDEX(BASE_SOUSCRIPTEURS!E:E,$I$3)/((1+PARAMETRES!$B$8)^INDEX(BASE_SOUSCRIPTEURS!E:E,$I$3)-1),0) -> 1055416.2 | C19: =IF(6<=INDEX(BASE_SOUSCRIPTEURS!E:E,$I$3),E18*PARAMETRES!$B$8,0) -> 425448.15 | D19: =IF(6<=INDEX(BASE_SOUSCRIPTEURS!E:E,$I$3),B19-C19,0) -> 629968 | E19: =IF(6<=INDEX(BASE_SOUSCRIPTEURS!E:E,$I$3),E18-D19,0) -> 11525693 | F19: =IF(6>INDEX(BASE_SOUSCRIPTEURS!E:E,$I$3),0,IFERROR(VLOOKUP(MIN((INDEX(BASE_SOUSCRIPTEURS!D:D,$I$3)+5),105),'CIMA_H (décès)'!$A$1:$C$112,3,FALSE()),1)) -> 0.0052712427 | G19: =IF(6<=INDEX(BASE_SOUSCRIPTEURS!E:E,$I$3),G18*(1-F19),0) -> 0.97417627 | H19: =IF(6<=INDEX(BASE_SOUSCRIPTEURS!E:E,$I$3),(1/(1+PARAMETRES!$B$7))^6*G18*F18*E19*INDEX(BASE_SOUSCRIPTEURS!G:G,$I$3),0) -> 26868.14 | I19: =IF(6<=INDEX(BASE_SOUSCRIPTEURS!E:E,$I$3),SUM(H19:H43),0) -> 240630.58
A20: 7 | B20: =IF(7<=INDEX(BASE_SOUSCRIPTEURS!E:E,$I$3),INDEX(BASE_SOUSCRIPTEURS!F:F,$I$3)*PARAMETRES!$B$8*(1+PARAMETRES!$B$8)^INDEX(BASE_SOUSCRIPTEURS!E:E,$I$3)/((1+PARAMETRES!$B$8)^INDEX(BASE_SOUSCRIPTEURS!E:E,$I$3)-1),0) -> 1055416.2 | C20: =IF(7<=INDEX(BASE_SOUSCRIPTEURS!E:E,$I$3),E19*PARAMETRES!$B$8,0) -> 403399.27 | D20: =IF(7<=INDEX(BASE_SOUSCRIPTEURS!E:E,$I$3),B20-C20,0) -> 652016.88 | E20: =IF(7<=INDEX(BASE_SOUSCRIPTEURS!E:E,$I$3),E19-D20,0) -> 10873677 | F20: =IF(7>INDEX(BASE_SOUSCRIPTEURS!E:E,$I$3),0,IFERROR(VLOOKUP(MIN((INDEX(BASE_SOUSCRIPTEURS!D:D,$I$3)+6),105),'CIMA_H (décès)'!$A$1:$C$112,3,FALSE()),1)) -> 0.0056625654 | G20: =IF(7<=INDEX(BASE_SOUSCRIPTEURS!E:E,$I$3),G19*(1-F20),0) -> 0.96865993 | H20: =IF(7<=INDEX(BASE_SOUSCRIPTEURS!E:E,$I$3),(1/(1+PARAMETRES!$B$7))^7*G19*F19*E20*INDEX(BASE_SOUSCRIPTEURS!G:G,$I$3),0) -> 26332.723 | I20: =IF(7<=INDEX(BASE_SOUSCRIPTEURS!E:E,$I$3),SUM(H20:H43),0) -> 213762.44
A21: 8 | B21: =IF(8<=INDEX(BASE_SOUSCRIPTEURS!E:E,$I$3),INDEX(BASE_SOUSCRIPTEURS!F:F,$I$3)*PARAMETRES!$B$8*(1+PARAMETRES!$B$8)^INDEX(BASE_SOUSCRIPTEURS!E:E,$I$3)/((1+PARAMETRES!$B$8)^INDEX(BASE_SOUSCRIPTEURS!E:E,$I$3)-1),0) -> 1055416.2 | C21: =IF(8<=INDEX(BASE_SOUSCRIPTEURS!E:E,$I$3),E20*PARAMETRES!$B$8,0) -> 380578.68 | D21: =IF(8<=INDEX(BASE_SOUSCRIPTEURS!E:E,$I$3),B21-C21,0) -> 674837.47 | E21: =IF(8<=INDEX(BASE_SOUSCRIPTEURS!E:E,$I$3),E20-D21,0) -> 10198839 | F21: =IF(8>INDEX(BASE_SOUSCRIPTEURS!E:E,$I$3),0,IFERROR(VLOOKUP(MIN((INDEX(BASE_SOUSCRIPTEURS!D:D,$I$3)+7),105),'CIMA_H (décès)'!$A$1:$C$112,3,FALSE()),1)) -> 0.0060409312 | G21: =IF(8<=INDEX(BASE_SOUSCRIPTEURS!E:E,$I$3),G20*(1-F21),0) -> 0.96280833 | H21: =IF(8<=INDEX(BASE_SOUSCRIPTEURS!E:E,$I$3),(1/(1+PARAMETRES!$B$7))^8*G20*F20*E21*INDEX(BASE_SOUSCRIPTEURS!G:G,$I$3),0) -> 25489.644 | I21: =IF(8<=INDEX(BASE_SOUSCRIPTEURS!E:E,$I$3),SUM(H21:H43),0) -> 187429.72
A22: 9 | B22: =IF(9<=INDEX(BASE_SOUSCRIPTEURS!E:E,$I$3),INDEX(BASE_SOUSCRIPTEURS!F:F,$I$3)*PARAMETRES!$B$8*(1+PARAMETRES!$B$8)^INDEX(BASE_SOUSCRIPTEURS!E:E,$I$3)/((1+PARAMETRES!$B$8)^INDEX(BASE_SOUSCRIPTEURS!E:E,$I$3)-1),0) -> 1055416.2 | C22: =IF(9<=INDEX(BASE_SOUSCRIPTEURS!E:E,$I$3),E21*PARAMETRES!$B$8,0) -> 356959.37 | D22: =IF(9<=INDEX(BASE_SOUSCRIPTEURS!E:E,$I$3),B22-C22,0) -> 698456.78 | E22: =IF(9<=INDEX(BASE_SOUSCRIPTEURS!E:E,$I$3),E21-D22,0) -> 9500382.4 | F22: =IF(9>INDEX(BASE_SOUSCRIPTEURS!E:E,$I$3),0,IFERROR(VLOOKUP(MIN((INDEX(BASE_SOUSCRIPTEURS!D:D,$I$3)+8),105),'CIMA_H (décès)'!$A$1:$C$112,3,FALSE()),1)) -> 0.0064075543 | G22: =IF(9<=INDEX(BASE_SOUSCRIPTEURS!E:E,$I$3),G21*(1-F22),0) -> 0.95663908 | H22: =IF(9<=INDEX(BASE_SOUSCRIPTEURS!E:E,$I$3),(1/(1+PARAMETRES!$B$7))^9*G21*F21*E22*INDEX(BASE_SOUSCRIPTEURS!G:G,$I$3),0) -> 24326.124 | I22: =IF(9<=INDEX(BASE_SOUSCRIPTEURS!E:E,$I$3),SUM(H22:H43),0) -> 161940.07
A23: 10 | B23: =IF(10<=INDEX(BASE_SOUSCRIPTEURS!E:E,$I$3),INDEX(BASE_SOUSCRIPTEURS!F:F,$I$3)*PARAMETRES!$B$8*(1+PARAMETRES!$B$8)^INDEX(BASE_SOUSCRIPTEURS!E:E,$I$3)/((1+PARAMETRES!$B$8)^INDEX(BASE_SOUSCRIPTEURS!E:E,$I$3)-1),0) -> 1055416.2 | C23: =IF(10<=INDEX(BASE_SOUSCRIPTEURS!E:E,$I$3),E22*PARAMETRES!$B$8,0) -> 332513.38 | D23: =IF(10<=INDEX(BASE_SOUSCRIPTEURS!E:E,$I$3),B23-C23,0) -> 722902.77 | E23: =IF(10<=INDEX(BASE_SOUSCRIPTEURS!E:E,$I$3),E22-D23,0) -> 8777479.6 | F23: =IF(10>INDEX(BASE_SOUSCRIPTEURS!E:E,$I$3),0,IFERROR(VLOOKUP(MIN((INDEX(BASE_SOUSCRIPTEURS!D:D,$I$3)+9),105),'CIMA_H (décès)'!$A$1:$C$112,3,FALSE()),1)) -> 0.0067740267 | G23: =IF(10<=INDEX(BASE_SOUSCRIPTEURS!E:E,$I$3),G22*(1-F23),0) -> 0.95015878 | H23: =IF(10<=INDEX(BASE_SOUSCRIPTEURS!E:E,$I$3),(1/(1+PARAMETRES!$B$7))^10*G22*F22*E23*INDEX(BASE_SOUSCRIPTEURS!G:G,$I$3),0) -> 22885.373 | I23: =IF(10<=INDEX(BASE_SOUSCRIPTEURS!E:E,$I$3),SUM(H23:H43),0) -> 137613.95
A24: 11 | B24: =IF(11<=INDEX(BASE_SOUSCRIPTEURS!E:E,$I$3),INDEX(BASE_SOUSCRIPTEURS!F:F,$I$3)*PARAMETRES!$B$8*(1+PARAMETRES!$B$8)^INDEX(BASE_SOUSCRIPTEURS!E:E,$I$3)/((1+PARAMETRES!$B$8)^INDEX(BASE_SOUSCRIPTEURS!E:E,$I$3)-1),0) -> 1055416.2 | C24: =IF(11<=INDEX(BASE_SOUSCRIPTEURS!E:E,$I$3),E23*PARAMETRES!$B$8,0) -> 307211.79 | D24: =IF(11<=INDEX(BASE_SOUSCRIPTEURS!E:E,$I$3),B24-C24,0) -> 748204.37 | E24: =IF(11<=INDEX(BASE_SOUSCRIPTEURS!E:E,$I$3),E23-D24,0) -> 8029275.2 | F24: =IF(11>INDEX(BASE_SOUSCRIPTEURS!E:E,$I$3),0,IFERROR(VLOOKUP(MIN((INDEX(BASE_SOUSCRIPTEURS!D:D,$I$3)+10),105),'CIMA_H (décès)'!$A$1:$C$112,3,FALSE()),1)) -> 0.0071410225 | G24: =IF(11<=INDEX(BASE_SOUSCRIPTEURS!E:E,$I$3),G23*(1-F24),0) -> 0.94337368 | H24: =IF(11<=INDEX(BASE_SOUSCRIPTEURS!E:E,$I$3),(1/(1+PARAMETRES!$B$7))^11*G23*F23*E24*INDEX(BASE_SOUSCRIPTEURS!G:G,$I$3),0) -> 21238.647 | I24: =IF(11<=INDEX(BASE_SOUSCRIPTEURS!E:E,$I$3),SUM(H24:H43),0) -> 114728.58
A25: 12 | B25: =IF(12<=INDEX(BASE_SOUSCRIPTEURS!E:E,$I$3),INDEX(BASE_SOUSCRIPTEURS!F:F,$I$3)*PARAMETRES!$B$8*(1+PARAMETRES!$B$8)^INDEX(BASE_SOUSCRIPTEURS!E:E,$I$3)/((1+PARAMETRES!$B$8)^INDEX(BASE_SOUSCRIPTEURS!E:E,$I$3)-1),0) -> 1055416.2 | C25: =IF(12<=INDEX(BASE_SOUSCRIPTEURS!E:E,$I$3),E24*PARAMETRES!$B$8,0) -> 281024.63 | D25: =IF(12<=INDEX(BASE_SOUSCRIPTEURS!E:E,$I$3),B25-C25,0) -> 774391.52 | E25: =IF(12<=INDEX(BASE_SOUSCRIPTEURS!E:E,$I$3),E24-D25,0) -> 7254883.7 | F25: =IF(12>INDEX(BASE_SOUSCRIPTEURS!E:E,$I$3),0,IFERROR(VLOOKUP(MIN((INDEX(BASE_SOUSCRIPTEURS!D:D,$I$3)+11),105),'CIMA_H (décès)'!$A$1:$C$112,3,FALSE()),1)) -> 0.0075403885 | G25: =IF(12<=INDEX(BASE_SOUSCRIPTEURS!E:E,$I$3),G24*(1-F25),0) -> 0.93626027 | H25: =IF(12<=INDEX(BASE_SOUSCRIPTEURS!E:E,$I$3),(1/(1+PARAMETRES!$B$7))^12*G24*F24*E25*INDEX(BASE_SOUSCRIPTEURS!G:G,$I$3),0) -> 19406.252 | I25: =IF(12<=INDEX(BASE_SOUSCRIPTEURS!E:E,$I$3),SUM(H25:H43),0) -> 93489.928
A26: 13 | B26: =IF(13<=INDEX(BASE_SOUSCRIPTEURS!E:E,$I$3),INDEX(BASE_SOUSCRIPTEURS!F:F,$I$3)*PARAMETRES!$B$8*(1+PARAMETRES!$B$8)^INDEX(BASE_SOUSCRIPTEURS!E:E,$I$3)/((1+PARAMETRES!$B$8)^INDEX(BASE_SOUSCRIPTEURS!E:E,$I$3)-1),0) -> 1055416.2 | C26: =IF(13<=INDEX(BASE_SOUSCRIPTEURS!E:E,$I$3),E25*PARAMETRES!$B$8,0) -> 253920.93 | D26: =IF(13<=INDEX(BASE_SOUSCRIPTEURS!E:E,$I$3),B26-C26,0) -> 801495.22 | E26: =IF(13<=INDEX(BASE_SOUSCRIPTEURS!E:E,$I$3),E25-D26,0) -> 6453388.5 | F26: =IF(13>INDEX(BASE_SOUSCRIPTEURS!E:E,$I$3),0,IFERROR(VLOOKUP(MIN((INDEX(BASE_SOUSCRIPTEURS!D:D,$I$3)+12),105),'CIMA_H (décès)'!$A$1:$C$112,3,FALSE()),1)) -> 0.007961953 | G26: =IF(13<=INDEX(BASE_SOUSCRIPTEURS!E:E,$I$3),G25*(1-F26),0) -> 0.92880581 | H26: =IF(13<=INDEX(BASE_SOUSCRIPTEURS!E:E,$I$3),(1/(1+PARAMETRES!$B$7))^13*G25*F25*E26*INDEX(BASE_SOUSCRIPTEURS!G:G,$I$3),0) -> 17478.527 | I26: =IF(13<=INDEX(BASE_SOUSCRIPTEURS!E:E,$I$3),SUM(H26:H43),0) -> 74083.677
A27: 14 | B27: =IF(14<=INDEX(BASE_SOUSCRIPTEURS!E:E,$I$3),INDEX(BASE_SOUSCRIPTEURS!F:F,$I$3)*PARAMETRES!$B$8*(1+PARAMETRES!$B$8)^INDEX(BASE_SOUSCRIPTEURS!E:E,$I$3)/((1+PARAMETRES!$B$8)^INDEX(BASE_SOUSCRIPTEURS!E:E,$I$3)-1),0) -> 1055416.2 | C27: =IF(14<=INDEX(BASE_SOUSCRIPTEURS!E:E,$I$3),E26*PARAMETRES!$B$8,0) -> 225868.6 | D27: =IF(14<=INDEX(BASE_SOUSCRIPTEURS!E:E,$I$3),B27-C27,0) -> 829547.56 | E27: =IF(14<=INDEX(BASE_SOUSCRIPTEURS!E:E,$I$3),E26-D27,0) -> 5623840.9 | F27: =IF(14>INDEX(BASE_SOUSCRIPTEURS!E:E,$I$3),0,IFERROR(VLOOKUP(MIN((INDEX(BASE_SOUSCRIPTEURS!D:D,$I$3)+13),105),'CIMA_H (décès)'!$A$1:$C$112,3,FALSE()),1)) -> 0.0084061678 | G27: =IF(14<=INDEX(BASE_SOUSCRIPTEURS!E:E,$I$3),G26*(1-F27),0) -> 0.92099811 | H27: =IF(14<=INDEX(BASE_SOUSCRIPTEURS!E:E,$I$3),(1/(1+PARAMETRES!$B$7))^14*G26*F26*E27*INDEX(BASE_SOUSCRIPTEURS!G:G,$I$3),0) -> 15415.724 | I27: =IF(14<=INDEX(BASE_SOUSCRIPTEURS!E:E,$I$3),SUM(H27:H43),0) -> 56605.15
A28: 15 | B28: =IF(15<=INDEX(BASE_SOUSCRIPTEURS!E:E,$I$3),INDEX(BASE_SOUSCRIPTEURS!F:F,$I$3)*PARAMETRES!$B$8*(1+PARAMETRES!$B$8)^INDEX(BASE_SOUSCRIPTEURS!E:E,$I$3)/((1+PARAMETRES!$B$8)^INDEX(BASE_SOUSCRIPTEURS!E:E,$I$3)-1),0) -> 1055416.2 | C28: =IF(15<=INDEX(BASE_SOUSCRIPTEURS!E:E,$I$3),E27*PARAMETRES!$B$8,0) -> 196834.43 | D28: =IF(15<=INDEX(BASE_SOUSCRIPTEURS!E:E,$I$3),B28-C28,0) -> 858581.72 | E28: =IF(15<=INDEX(BASE_SOUSCRIPTEURS!E:E,$I$3),E27-D28,0) -> 4765259.2 | F28: =IF(15>INDEX(BASE_SOUSCRIPTEURS!E:E,$I$3),0,IFERROR(VLOOKUP(MIN((INDEX(BASE_SOUSCRIPTEURS!D:D,$I$3)+14),105),'CIMA_H (décès)'!$A$1:$C$112,3,FALSE()),1)) -> 0.0088837658 | G28: =IF(15<=INDEX(BASE_SOUSCRIPTEURS!E:E,$I$3),G27*(1-F28),0) -> 0.91281618 | H28: =IF(15<=INDEX(BASE_SOUSCRIPTEURS!E:E,$I$3),(1/(1+PARAMETRES!$B$7))^15*G27*F27*E28*INDEX(BASE_SOUSCRIPTEURS!G:G,$I$3),0) -> 13212.632 | I28: =IF(15<=INDEX(BASE_SOUSCRIPTEURS!E:E,$I$3),SUM(H28:H43),0) -> 41189.426
A29: 16 | B29: =IF(16<=INDEX(BASE_SOUSCRIPTEURS!E:E,$I$3),INDEX(BASE_SOUSCRIPTEURS!F:F,$I$3)*PARAMETRES!$B$8*(1+PARAMETRES!$B$8)^INDEX(BASE_SOUSCRIPTEURS!E:E,$I$3)/((1+PARAMETRES!$B$8)^INDEX(BASE_SOUSCRIPTEURS!E:E,$I$3)-1),0) -> 1055416.2 | C29: =IF(16<=INDEX(BASE_SOUSCRIPTEURS!E:E,$I$3),E28*PARAMETRES!$B$8,0) -> 166784.07 | D29: =IF(16<=INDEX(BASE_SOUSCRIPTEURS!E:E,$I$3),B29-C29,0) -> 888632.08 | E29: =IF(16<=INDEX(BASE_SOUSCRIPTEURS!E:E,$I$3),E28-D29,0) -> 3876627.1 | F29: =IF(16>INDEX(BASE_SOUSCRIPTEURS!E:E,$I$3),0,IFERROR(VLOOKUP(MIN((INDEX(BASE_SOUSCRIPTEURS!D:D,$I$3)+15),105),'CIMA_H (décès)'!$A$1:$C$112,3,FALSE()),1)) -> 0.0093751265 | G29: =IF(16<=INDEX(BASE_SOUSCRIPTEURS!E:E,$I$3),G28*(1-F29),0) -> 0.90425842 | H29: =IF(16<=INDEX(BASE_SOUSCRIPTEURS!E:E,$I$3),(1/(1+PARAMETRES!$B$7))^16*G28*F28*E29*INDEX(BASE_SOUSCRIPTEURS!G:G,$I$3),0) -> 10877.776 | I29: =IF(16<=INDEX(BASE_SOUSCRIPTEURS!E:E,$I$3),SUM(H29:H43),0) -> 27976.794
A30: 17 | B30: =IF(17<=INDEX(BASE_SOUSCRIPTEURS!E:E,$I$3),INDEX(BASE_SOUSCRIPTEURS!F:F,$I$3)*PARAMETRES!$B$8*(1+PARAMETRES!$B$8)^INDEX(BASE_SOUSCRIPTEURS!E:E,$I$3)/((1+PARAMETRES!$B$8)^INDEX(BASE_SOUSCRIPTEURS!E:E,$I$3)-1),0) -> 1055416.2 | C30: =IF(17<=INDEX(BASE_SOUSCRIPTEURS!E:E,$I$3),E29*PARAMETRES!$B$8,0) -> 135681.95 | D30: =IF(17<=INDEX(BASE_SOUSCRIPTEURS!E:E,$I$3),B30-C30,0) -> 919734.2 | E30: =IF(17<=INDEX(BASE_SOUSCRIPTEURS!E:E,$I$3),E29-D30,0) -> 2956892.9 | F30: =IF(17>INDEX(BASE_SOUSCRIPTEURS!E:E,$I$3),0,IFERROR(VLOOKUP(MIN((INDEX(BASE_SOUSCRIPTEURS!D:D,$I$3)+16),105),'CIMA_H (décès)'!$A$1:$C$112,3,FALSE()),1)) -> 0.0098848779 | G30: =IF(17<=INDEX(BASE_SOUSCRIPTEURS!E:E,$I$3),G29*(1-F30),0) -> 0.89531993 | H30: =IF(17<=INDEX(BASE_SOUSCRIPTEURS!E:E,$I$3),(1/(1+PARAMETRES!$B$7))^17*G29*F29*E30*INDEX(BASE_SOUSCRIPTEURS!G:G,$I$3),0) -> 8380.5129 | I30: =IF(17<=INDEX(BASE_SOUSCRIPTEURS!E:E,$I$3),SUM(H30:H43),0) -> 17099.018
A31: 18 | B31: =IF(18<=INDEX(BASE_SOUSCRIPTEURS!E:E,$I$3),INDEX(BASE_SOUSCRIPTEURS!F:F,$I$3)*PARAMETRES!$B$8*(1+PARAMETRES!$B$8)^INDEX(BASE_SOUSCRIPTEURS!E:E,$I$3)/((1+PARAMETRES!$B$8)^INDEX(BASE_SOUSCRIPTEURS!E:E,$I$3)-1),0) -> 1055416.2 | C31: =IF(18<=INDEX(BASE_SOUSCRIPTEURS!E:E,$I$3),E30*PARAMETRES!$B$8,0) -> 103491.25 | D31: =IF(18<=INDEX(BASE_SOUSCRIPTEURS!E:E,$I$3),B31-C31,0) -> 951924.9 | E31: =IF(18<=INDEX(BASE_SOUSCRIPTEURS!E:E,$I$3),E30-D31,0) -> 2004968 | F31: =IF(18>INDEX(BASE_SOUSCRIPTEURS!E:E,$I$3),0,IFERROR(VLOOKUP(MIN((INDEX(BASE_SOUSCRIPTEURS!D:D,$I$3)+17),105),'CIMA_H (décès)'!$A$1:$C$112,3,FALSE()),1)) -> 0.010594716 | G31: =IF(18<=INDEX(BASE_SOUSCRIPTEURS!E:E,$I$3),G30*(1-F31),0) -> 0.88583427 | H31: =IF(18<=INDEX(BASE_SOUSCRIPTEURS!E:E,$I$3),(1/(1+PARAMETRES!$B$7))^18*G30*F30*E31*INDEX(BASE_SOUSCRIPTEURS!G:G,$I$3),0) -> 5731.6804 | I31: =IF(18<=INDEX(BASE_SOUSCRIPTEURS!E:E,$I$3),SUM(H31:H43),0) -> 8718.5055
A32: 19 | B32: =IF(19<=INDEX(BASE_SOUSCRIPTEURS!E:E,$I$3),INDEX(BASE_SOUSCRIPTEURS!F:F,$I$3)*PARAMETRES!$B$8*(1+PARAMETRES!$B$8)^INDEX(BASE_SOUSCRIPTEURS!E:E,$I$3)/((1+PARAMETRES!$B$8)^INDEX(BASE_SOUSCRIPTEURS!E:E,$I$3)-1),0) -> 1055416.2 | C32: =IF(19<=INDEX(BASE_SOUSCRIPTEURS!E:E,$I$3),E31*PARAMETRES!$B$8,0) -> 70173.881 | D32: =IF(19<=INDEX(BASE_SOUSCRIPTEURS!E:E,$I$3),B32-C32,0) -> 985242.27 | E32: =IF(19<=INDEX(BASE_SOUSCRIPTEURS!E:E,$I$3),E31-D32,0) -> 1019725.8 | F32: =IF(19>INDEX(BASE_SOUSCRIPTEURS!E:E,$I$3),0,IFERROR(VLOOKUP(MIN((INDEX(BASE_SOUSCRIPTEURS!D:D,$I$3)+18),105),'CIMA_H (décès)'!$A$1:$C$112,3,FALSE()),1)) -> 0.011415878 | G32: =IF(19<=INDEX(BASE_SOUSCRIPTEURS!E:E,$I$3),G31*(1-F32),0) -> 0.87572169 | H32: =IF(19<=INDEX(BASE_SOUSCRIPTEURS!E:E,$I$3),(1/(1+PARAMETRES!$B$7))^19*G31*F31*E32*INDEX(BASE_SOUSCRIPTEURS!G:G,$I$3),0) -> 2986.8252 | I32: =IF(19<=INDEX(BASE_SOUSCRIPTEURS!E:E,$I$3),SUM(H32:H43),0) -> 2986.8252
A33: 20 | B33: =IF(20<=INDEX(BASE_SOUSCRIPTEURS!E:E,$I$3),INDEX(BASE_SOUSCRIPTEURS!F:F,$I$3)*PARAMETRES!$B$8*(1+PARAMETRES!$B$8)^INDEX(BASE_SOUSCRIPTEURS!E:E,$I$3)/((1+PARAMETRES!$B$8)^INDEX(BASE_SOUSCRIPTEURS!E:E,$I$3)-1),0) -> 1055416.2 | C33: =IF(20<=INDEX(BASE_SOUSCRIPTEURS!E:E,$I$3),E32*PARAMETRES!$B$8,0) -> 35690.401 | D33: =IF(20<=INDEX(BASE_SOUSCRIPTEURS!E:E,$I$3),B33-C33,0) -> 1019725.8 | E33: =IF(20<=INDEX(BASE_SOUSCRIPTEURS!E:E,$I$3),E32-D33,0) -> -4.8312359e-08 | F33: =IF(20>INDEX(BASE_SOUSCRIPTEURS!E:E,$I$3),0,IFERROR(VLOOKUP(MIN((INDEX(BASE_SOUSCRIPTEURS!D:D,$I$3)+19),105),'CIMA_H (décès)'!$A$1:$C$112,3,FALSE()),1)) -> 0.012456878 | G33: =IF(20<=INDEX(BASE_SOUSCRIPTEURS!E:E,$I$3),G32*(1-F33),0) -> 0.86481294 | H33: =IF(20<=INDEX(BASE_SOUSCRIPTEURS!E:E,$I$3),(1/(1+PARAMETRES!$B$7))^20*G32*F32*E33*INDEX(BASE_SOUSCRIPTEURS!G:G,$I$3),0) -> -1.4563908e-10 | I33: =IF(20<=INDEX(BASE_SOUSCRIPTEURS!E:E,$I$3),SUM(H33:H43),0) -> -1.4563908e-10
A34: 21 | B34: =IF(21<=INDEX(BASE_SOUSCRIPTEURS!E:E,$I$3),INDEX(BASE_SOUSCRIPTEURS!F:F,$I$3)*PARAMETRES!$B$8*(1+PARAMETRES!$B$8)^INDEX(BASE_SOUSCRIPTEURS!E:E,$I$3)/((1+PARAMETRES!$B$8)^INDEX(BASE_SOUSCRIPTEURS!E:E,$I$3)-1),0) -> 0 | C34: =IF(21<=INDEX(BASE_SOUSCRIPTEURS!E:E,$I$3),E33*PARAMETRES!$B$8,0) -> 0 | D34: =IF(21<=INDEX(BASE_SOUSCRIPTEURS!E:E,$I$3),B34-C34,0) -> 0 | E34: =IF(21<=INDEX(BASE_SOUSCRIPTEURS!E:E,$I$3),E33-D34,0) -> 0 | F34: =IF(21>INDEX(BASE_SOUSCRIPTEURS!E:E,$I$3),0,IFERROR(VLOOKUP(MIN((INDEX(BASE_SOUSCRIPTEURS!D:D,$I$3)+20),105),'CIMA_H (décès)'!$A$1:$C$112,3,FALSE()),1)) -> 0 | G34: =IF(21<=INDEX(BASE_SOUSCRIPTEURS!E:E,$I$3),G33*(1-F34),0) -> 0 | H34: =IF(21<=INDEX(BASE_SOUSCRIPTEURS!E:E,$I$3),(1/(1+PARAMETRES!$B$7))^21*G33*F33*E34*INDEX(BASE_SOUSCRIPTEURS!G:G,$I$3),0) -> 0 | I34: =IF(21<=INDEX(BASE_SOUSCRIPTEURS!E:E,$I$3),SUM(H34:H43),0) -> 0
